Workbook

Sheet PQ_Harian
A1: Nama Test | B1: 1 | C1: 2 | D1: 3 | E1: 4 | F1: 5 | G1: 6 | H1: 7 | I1: 8 | J1: 9 | K1: 10 | L1: 11 | M1: 12 | N1: 13 | O1: 14 | P1: 15 | Q1: 16 | R1: 17 | S1: 18 | T1: 19 | U1: 20 | V1: 21 | W1: 22 | X1: 23 | Y1: 24 | Z1: 25 | AA1: 26 | AB1: 27 | AC1: 28 | AD1: 29 | AE1: 30 | AF1: 31 | AG1: Total
A2: Snibe Vitamin B12 | C2: 1 | I2: 2 | K2: 1 | L2: 1 | P2: 1 | R2: 2 | X2: 1 | Y2: 1 | AE2: 1 | AG2: 11
A3: Snibe Asam Folat | C3: 1 | K3: 1 | L3: 1 | P3: 1 | R3: 2 | X3: 1 | Y3: 1 | AE3: 1 | AG3: 9
A4: Ferritin | C4: 2 | G4: 3 | I4: 1 | J4: 1 | K4: 1 | L4: 2 | N4: 3 | P4: 3 | R4: 1 | W4: 2 | X4: 1 | Z4: 2 | AB4: 2 | AD4: 2 | AE4: 2 | AG4: 28
A5: INDIKO Iron | C5: 5 | D5: 4 | E5: 7 | F5: 3 | G5: 4 | I5: 2 | J5: 1 | K5: 1 | L5: 3 | M5: 3 | N5: 1 | R5: 1 | S5: 1 | T5: 1 | U5: 3 | W5: 3 | X5: 1 | Y5: 1 | Z5: 3 | AA5: 1 | AB5: 1 | AD5: 2 | AE5: 3 | AG5: 55
A6: PATHFAST D-dimer | E6: 2 | F6: 1 | I6: 1 | N6: 2 | AG6: 6
A7: PATHFAST Trop I | C7: 5 | D7: 2 | E7: 1 | F7: 1 | G7: 1 | I7: 2 | J7: 1 | K7: 1 | L7: 1 | M7: 5 | N7: 2 | P7: 3 | R7: 3 | S7: 1 | U7: 1 | W7: 7 | X7: 1 | Y7: 3 | AD7: 2 | AG7: 43
A8: Elecsys Vitamin D | C8: 2 | D8: 2 | E8: 2 | F8: 2 | G8: 7 | I8: 5 | J8: 4 | K8: 1 | L8: 3 | M8: 2 | N8: 4 | P8: 5 | R8: 3 | S8: 3 | T8: 4 | U8: 2 | W8: 2 | X8: 7 | Y8: 1 | Z8: 1 | AA8: 4 | AB8: 2 | AD8: 2 | AE8: 3 | AG8: 73
A9: Leptospira IgG/IgM | E9: 1 | F9: 1 | AB9: 1 | AG9: 3
A10: Euroimmun IgE Inhalasi | E10: 2 | G10: 1 | I10: 1 | R10: 1 | T10: 1 | U10: 1 | AG10: 7
A11: Vidas AMH | E11: 1 | I11: 1 | S11: 1 | W11: 1 | X11: 1 | AD11: 1 | AG11: 6
A12: Euroimmun IgE Makanan Asia | E12: 1 | G12: 1 | T12: 1 | AG12: 3
A13: Euroimmun IgE Atopi | C13: 2 | I13: 1 | J13: 2 | K13: 1 | L13: 1 | M13: 1 | N13: 2 | R13: 2 | S13: 2 | T13: 1 | U13: 1 | W13: 1 | Y13: 1 | Z13: 3 | AA13: 2 | AB13: 1 | AD13: 3 | AE13: 3 | AG13: 30
A14: Chikungunya IgM | C14: 1 | AA14: 2 | AE14: 1 | AG14: 4
A15: Anti Toxo Avidity IgG | I15: 1 | AE15: 1 | AG15: 2
A16: Anti HAV Total | M16: 1 | AG16: 1
A17: Euroimmun ANA Profile | D17: 1 | G17: 1 | I17: 1 | K17: 2 | M17: 1 | N17: 3 | R17: 1 | U17: 1 | W17: 2 | Z17: 1 | AA17: 1 | AB17: 2 | AD17: 1 | AG17: 18
A18: HBsAg | D18: 1 | E18: 2 | G18: 2 | I18: 2 | J18: 1 | N18: 1 | U18: 1 | W18: 1 | X18: 2 | AD18: 2 | AE18: 1 | AG18: 16
A19: Hbsag rapid | D19: 1 | R19: 3 | T19: 1 | U19: 3 | X19: 2 | Y19: 1 | Z19: 1 | AA19: 1 | AB19: 5 | AD19: 1 | AE19: 1 | AG19: 20
A20: Anti-HBS | E20: 1 | G20: 2 | P20: 5 | U20: 1 | X20: 2 | Z20: 1 | AG20: 12
A21: Anti HBc Total | D21: 1 | F21: 1 | G21: 1 | W21: 1 | AB21: 1 | AD21: 1 | AG21: 6
A22: PIMA CD4 | C22: 1 | F22: 1 | J22: 1 | K22: 1 | L22: 1 | P22: 1 | R22: 1 | AD22: 1 | AG22: 8
A23: HBeAg | M23: 2 | P23: 1 | S23: 1 | T23: 2 | U23: 1 | Y23: 2 | AG23: 9
A24: Anti HAV IgM | C24: 2 | E24: 1 | K24: 1 | N24: 1 | P24: 1 | R24: 1 | T24: 1 | Y24: 2 | AA24: 1 | AB24: 1 | AG24: 12
A25: Toxo IgG | C25: 1 | D25: 2 | E25: 3 | F25: 1 | G25: 4 | I25: 1 | J25: 2 | K25: 1 | R25: 2 | T25: 1 | U25: 2 | W25: 3 | Y25: 1 | AB25: 1 | AD25: 2 | AE25: 2 | AG25: 29
A26: Toxo IgM | C26: 2 | E26: 2 | F26: 1 | G26: 2 | I26: 1 | K26: 1 | P26: 1 | R26: 3 | U26: 1 | W26: 2 | Y26: 2 | AB26: 1 | AD26: 1 | AE26: 2 | AG26: 22
A27: Rubella IgG | D27: 1 | E27: 3 | F27: 3 | G27: 2 | J27: 3 | N27: 1 | R27: 1 | S27: 3 | T27: 1 | U27: 2 | W27: 3 | X27: 3 | Y27: 1 | AA27: 1 | AB27: 1 | AE27: 3 | AG27: 32
A28: Rubella IgM | F28: 1 | I28: 1 | P28: 1 | R28: 1 | W28: 2 | AE28: 1 | AG28: 7
A29: CMV IgG | F29: 1 | G29: 1 | I29: 1 | J29: 2 | K29: 1 | U29: 1 | W29: 1 | AD29: 1 | AE29: 1 | AG29: 10
A30: CMV IgM | F30: 1 | K30: 1 | P30: 1 | R30: 1 | U30: 1 | AD30: 1 | AE30: 1 | AG30: 7
A31: PATHFAST Hs-CRP | D31: 1 | E31: 1 | G31: 2 | I31: 2 | J31: 2 | M31: 1 | N31: 2 | S31: 1 | X31: 1 | AA31: 1 | AG31: 14
A32: IgE Total | C32: 2 | D32: 2 | E32: 2 | F32: 1 | G32: 1 | I32: 2 | J32: 2 | M32: 3 | N32: 3 | R32: 2 | S32: 1 | W32: 2 | Z32: 2 | AA32: 3 | AD32: 2 | AE32: 1 | AG32: 31
A33: Fokus HIV | C33: 1 | E33: 3 | G33: 1 | N33: 2 | R33: 3 | T33: 1 | U33: 2 | X33: 2 | AB33: 2 | AD33: 1 | AE33: 2 | AG33: 20
A34: AFP | E34: 2 | G34: 1 | M34: 1 | N34: 1 | P34: 1 | U34: 1 | Z34: 1 | AB34: 12 | AE34: 1 | AG34: 21
A35: Total PSA | E35: 1 | G35: 2 | K35: 1 | N35: 2 | S35: 1 | W35: 2 | X35: 1 | Z35: 1 | AB35: 1 | AE35: 2 | AG35: 14
A36: CEA | E36: 2 | F36: 1 | G36: 2 | I36: 1 | M36: 1 | N36: 2 | P36: 1 | W36: 3 | X36: 1 | Y36: 1 | Z36: 2 | AG36: 17
A37: Ca 125 | E37: 3 | G37: 3 | I37: 1 | J37: 1 | L37: 1 | M37: 1 | N37: 1 | P37: 1 | T37: 1 | X37: 2 | AA37: 1 | AB37: 3 | AE37: 1 | AG37: 20
A38: Ca 19-9 | D38: 1 | E38: 2 | K38: 3 | M38: 1 | P38: 1 | AB38: 12 | AE38: 1 | AG38: 21
A39: Ca 15-3 | E39: 2 | G39: 1 | I39: 1 | L39: 1 | M39: 1 | N39: 1 | AA39: 1 | AB39: 1 | AG39: 9
A40: Elektrolit | C40: 12 | D40: 3 | E40: 38 | G40: 1 | I40: 6 | J40: 2 | K40: 1 | M40: 10 | N40: 1 | P40: 7 | R40: 6 | S40: 6 | W40: 8 | X40: 4 | Y40: 6 | AD40: 1 | AE40: 6 | AG40: 118
...

Sheet Juli2026
A2: Item Code | C2: REAGEN | D2: Qty/kit | E2: AVG Sampel per bulan 2022 | F2: AVG Sampel per bulan 2023 | G2: Saldo awal (Stok Juni 2026) | H2: PEMANTAUAN STOCK REAGEN LAB PK | AM2: QC | AN2: Total Pemakaian | AO2: Sisa stock ongoing | AP2: Buffer Stock | AR2: Tanggal PR | AT2: Tanggal PR | AV2: Tanggal Terima | AX2: Penambahan stock | BA2: Saldo akhir | BB2: NOTE
H3: 1 | I3: 2 | J3: 3 | K3: 4 | L3: 5 | M3: 6 | N3: 7 | O3: 8 | P3: 9 | Q3: 10 | R3: 11 | S3: 12 | T3: 13 | U3: 14 | V3: 15 | W3: 16 | X3: 17 | Y3: 18 | Z3: 19 | AA3: 20 | AB3: 21 | AC3: 22 | AD3: 23 | AE3: 24 | AF3: 25 | AG3: 26 | AH3: 27 | AI3: 28 | AJ3: 29 | AK3: 30 | AL3: 31 | AP3: Qty | AQ3: Satuan | AR3: Reagent 1 | AS3: Kit | AT3: Reagent 2 | AU3: Kit | AV3: Reagent 1 | AW3: Reagent 2 | AX3: Order ke 1 | AY3: Order ke 2 | AZ3: Jumlah
A4: =AO4 -> 16 | C4: Ca 15-3 | D4: 30 | E4: 22 | F4: 19 | G4: 29 | H4: {=IFERROR(INDEX(PQ_Juli!$B$2:$AF$1048,MATCH($C4,PQ_Juli!$A$2:$A$1048,0),MATCH(H$3&"",PQ_Juli!$B$1:$AF$1&"",0)),0)} -> 0 | I4: {=IFERROR(INDEX(PQ_Juli!$B$2:$AF$1048,MATCH($C4,PQ_Juli!$A$2:$A$1048,0),MATCH(I$3&"",PQ_Juli!$B$1:$AF$1&"",0)),0)} -> 0 | J4: {=IFERROR(INDEX(PQ_Juli!$B$2:$AF$1048,MATCH($C4,PQ_Juli!$A$2:$A$1048,0),MATCH(J$3&"",PQ_Juli!$B$1:$AF$1&"",0)),0)} -> 1 | K4: {=IFERROR(INDEX(PQ_Juli!$B$2:$AF$1048,MATCH($C4,PQ_Juli!$A$2:$A$1048,0),MATCH(K$3&"",PQ_Juli!$B$1:$AF$1&"",0)),0)} -> 0 | M4: {=IFERROR(INDEX(PQ_Juli!$B$2:$AF$1048,MATCH($C4,PQ_Juli!$A$2:$A$1048,0),MATCH(M$3&"",PQ_Juli!$B$1:$AF$1&"",0)),0)} -> 0 | N4: {=IFERROR(INDEX(PQ_Juli!$B$2:$AF$1048,MATCH($C4,PQ_Juli!$A$2:$A$1048,0),MATCH(N$3&"",PQ_Juli!$B$1:$AF$1&"",0)),0)} -> 1 | O4: {=IFERROR(INDEX(PQ_Juli!$B$2:$AF$1048,MATCH($C4,PQ_Juli!$A$2:$A$1048,0),MATCH(O$3&"",PQ_Juli!$B$1:$AF$1&"",0)),0)} -> 0 | P4: {=IFERROR(INDEX(PQ_Juli!$B$2:$AF$1048,MATCH($C4,PQ_Juli!$A$2:$A$1048,0),MATCH(P$3&"",PQ_Juli!$B$1:$AF$1&"",0)),0)} -> 0 | Q4: {=IFERROR(INDEX(PQ_Juli!$B$2:$AF$1048,MATCH($C4,PQ_Juli!$A$2:$A$1048,0),MATCH(Q$3&"",PQ_Juli!$B$1:$AF$1&"",0)),0)} -> 1 | R4: {=IFERROR(INDEX(PQ_Juli!$B$2:$AF$1048,MATCH($C4,PQ_Juli!$A$2:$A$1048,0),MATCH(R$3&"",PQ_Juli!$B$1:$AF$1&"",0)),0)} -> 0 | T4: {=IFERROR(INDEX(PQ_Juli!$B$2:$AF$1048,MATCH($C4,PQ_Juli!$A$2:$A$1048,0),MATCH(T$3&"",PQ_Juli!$B$1:$AF$1&"",0)),0)} -> 1 | U4: {=IFERROR(INDEX(PQ_Juli!$B$2:$AF$1048,MATCH($C4,PQ_Juli!$A$2:$A$1048,0),MATCH(U$3&"",PQ_Juli!$B$1:$AF$1&"",0)),0)} -> 0 | V4: {=IFERROR(INDEX(PQ_Juli!$B$2:$AF$1048,MATCH($C4,PQ_Juli!$A$2:$A$1048,0),MATCH(V$3&"",PQ_Juli!$B$1:$AF$1&"",0)),0)} -> 0 | W4: {=IFERROR(INDEX(PQ_Juli!$B$2:$AF$1048,MATCH($C4,PQ_Juli!$A$2:$A$1048,0),MATCH(W$3&"",PQ_Juli!$B$1:$AF$1&"",0)),0)} -> 1 | X4: {=IFERROR(INDEX(PQ_Juli!$B$2:$AF$1048,MATCH($C4,PQ_Juli!$A$2:$A$1048,0),MATCH(X$3&"",PQ_Juli!$B$1:$AF$1&"",0)),0)} -> 1 | Y4: {=IFERROR(INDEX(PQ_Juli!$B$2:$AF$1048,MATCH($C4,PQ_Juli!$A$2:$A$1048,0),MATCH(Y$3&"",PQ_Juli!$B$1:$AF$1&"",0)),0)} -> 0 | AA4: {=IFERROR(INDEX(PQ_Juli!$B$2:$AF$1048,MATCH($C4,PQ_Juli!$A$2:$A$1048,0),MATCH(AA$3&"",PQ_Juli!$B$1:$AF$1&"",0)),0)} -> 0 | AB4: {=IFERROR(INDEX(PQ_Juli!$B$2:$AF$1048,MATCH($C4,PQ_Juli!$A$2:$A$1048,0),MATCH(AB$3&"",PQ_Juli!$B$1:$AF$1&"",0)),0)} -> 1 | AC4: {=IFERROR(INDEX(PQ_Juli!$B$2:$AF$1048,MATCH($C4,PQ_Juli!$A$2:$A$1048,0),MATCH(AC$3&"",PQ_Juli!$B$1:$AF$1&"",0)),0)} -> 0 | AD4: {=IFERROR(INDEX(PQ_Juli!$B$2:$AF$1048,MATCH($C4,PQ_Juli!$A$2:$A$1048,0),MATCH(AD$3&"",PQ_Juli!$B$1:$AF$1&"",0)),0)} -> 0 | AE4: {=IFERROR(INDEX(PQ_Juli!$B$2:$AF$1048,MATCH($C4,PQ_Juli!$A$2:$A$1048,0),MATCH(AE$3&"",PQ_Juli!$B$1:$AF$1&"",0)),0)} -> 1 | AF4: {=IFERROR(INDEX(PQ_Juli!$B$2:$AF$1048,MATCH($C4,PQ_Juli!$A$2:$A$1048,0),MATCH(AF$3&"",PQ_Juli!$B$1:$AF$1&"",0)),0)} -> 0 | AH4: {=IFERROR(INDEX(PQ_Juli!$B$2:$AF$1048,MATCH($C4,PQ_Juli!$A$2:$A$1048,0),MATCH(AH$3&"",PQ_Juli!$B$1:$AF$1&"",0)),0)} -> 0 | AI4: {=IFERROR(INDEX(PQ_Juli!$B$2:$AF$1048,MATCH($C4,PQ_Juli!$A$2:$A$1048,0),MATCH(AI$3&"",PQ_Juli!$B$1:$AF$1&"",0)),0)} -> 1 | AJ4: {=IFERROR(INDEX(PQ_Juli!$B$2:$AF$1048,MATCH($C4,PQ_Juli!$A$2:$A$1048,0),MATCH(AJ$3&"",PQ_Juli!$B$1:$AF$1&"",0)),0)} -> 0 | AK4: {=IFERROR(INDEX(PQ_Juli!$B$2:$AF$1048,MATCH($C4,PQ_Juli!$A$2:$A$1048,0),MATCH(AK$3&"",PQ_Juli!$B$1:$AF$1&"",0)),0)} -> 0 | AL4: {=IFERROR(INDEX(PQ_Juli!$B$2:$AF$1048,MATCH($C4,PQ_Juli!$A$2:$A$1048,0),MATCH(AL$3&"",PQ_Juli!$B$1:$AF$1&"",0)),0)} -> 1 | AM4: 3 | AN4: =SUM(H4:AL4)+AM4 -> 13 | AO4: =(G4-AN4)+AZ4 -> 16 | AP4: 20 | AQ4: Pcs | AX4: =IFERROR(IF(AV4="",0,$D4*AS4),0) -> 0 | AY4: =IFERROR(IF(AW4="",0,$D4*AU4),0) -> 0 | AZ4: =AX4+AY4 -> 0 | BA4: =(G4-AN4)+AZ4 -> 16 | BN4: 4
A5: =AO5 -> 68 | C5: Ca 19-9 | D5: 30 | E5: 21 | F5: 21 | G5: 25 | H5: {=IFERROR(INDEX(PQ_Juli!$B$2:$AF$1048,MATCH($C5,PQ_Juli!$A$2:$A$1048,0),MATCH(H$3&"",PQ_Juli!$B$1:$AF$1&"",0)),0)} -> 2 | I5: {=IFERROR(INDEX(PQ_Juli!$B$2:$AF$1048,MATCH($C5,PQ_Juli!$A$2:$A$1048,0),MATCH(I$3&"",PQ_Juli!$B$1:$AF$1&"",0)),0)} -> 2 | J5: {=IFERROR(INDEX(PQ_Juli!$B$2:$AF$1048,MATCH($C5,PQ_Juli!$A$2:$A$1048,0),MATCH(J$3&"",PQ_Juli!$B$1:$AF$1&"",0)),0)} -> 3 | K5: {=IFERROR(INDEX(PQ_Juli!$B$2:$AF$1048,MATCH($C5,PQ_Juli!$A$2:$A$1048,0),MATCH(K$3&"",PQ_Juli!$B$1:$AF$1&"",0)),0)} -> 0 | M5: {=IFERROR(INDEX(PQ_Juli!$B$2:$AF$1048,MATCH($C5,PQ_Juli!$A$2:$A$1048,0),MATCH(M$3&"",PQ_Juli!$B$1:$AF$1&"",0)),0)} -> 0 | N5: {=IFERROR(INDEX(PQ_Juli!$B$2:$AF$1048,MATCH($C5,PQ_Juli!$A$2:$A$1048,0),MATCH(N$3&"",PQ_Juli!$B$1:$AF$1&"",0)),0)} -> 1 | O5: {=IFERROR(INDEX(PQ_Juli!$B$2:$AF$1048,MATCH($C5,PQ_Juli!$A$2:$A$1048,0),MATCH(O$3&"",PQ_Juli!$B$1:$AF$1&"",0)),0)} -> 0 | P5: {=IFERROR(INDEX(PQ_Juli!$B$2:$AF$1048,MATCH($C5,PQ_Juli!$A$2:$A$1048,0),MATCH(P$3&"",PQ_Juli!$B$1:$AF$1&"",0)),0)} -> 0 | Q5: {=IFERROR(INDEX(PQ_Juli!$B$2:$AF$1048,MATCH($C5,PQ_Juli!$A$2:$A$1048,0),MATCH(Q$3&"",PQ_Juli!$B$1:$AF$1&"",0)),0)} -> 1 | R5: {=IFERROR(INDEX(PQ_Juli!$B$2:$AF$1048,MATCH($C5,PQ_Juli!$A$2:$A$1048,0),MATCH(R$3&"",PQ_Juli!$B$1:$AF$1&"",0)),0)} -> 0 | T5: {=IFERROR(INDEX(PQ_Juli!$B$2:$AF$1048,MATCH($C5,PQ_Juli!$A$2:$A$1048,0),MATCH(T$3&"",PQ_Juli!$B$1:$AF$1&"",0)),0)} -> 0 | U5: {=IFERROR(INDEX(PQ_Juli!$B$2:$AF$1048,MATCH($C5,PQ_Juli!$A$2:$A$1048,0),MATCH(U$3&"",PQ_Juli!$B$1:$AF$1&"",0)),0)} -> 0 | V5: {=IFERROR(INDEX(PQ_Juli!$B$2:$AF$1048,MATCH($C5,PQ_Juli!$A$2:$A$1048,0),MATCH(V$3&"",PQ_Juli!$B$1:$AF$1&"",0)),0)} -> 0 | W5: {=IFERROR(INDEX(PQ_Juli!$B$2:$AF$1048,MATCH($C5,PQ_Juli!$A$2:$A$1048,0),MATCH(W$3&"",PQ_Juli!$B$1:$AF$1&"",0)),0)} -> 3 | X5: {=IFERROR(INDEX(PQ_Juli!$B$2:$AF$1048,MATCH($C5,PQ_Juli!$A$2:$A$1048,0),MATCH(X$3&"",PQ_Juli!$B$1:$AF$1&"",0)),0)} -> 0 | Y5: {=IFERROR(INDEX(PQ_Juli!$B$2:$AF$1048,MATCH($C5,PQ_Juli!$A$2:$A$1048,0),MATCH(Y$3&"",PQ_Juli!$B$1:$AF$1&"",0)),0)} -> 0 | AA5: {=IFERROR(INDEX(PQ_Juli!$B$2:$AF$1048,MATCH($C5,PQ_Juli!$A$2:$A$1048,0),MATCH(AA$3&"",PQ_Juli!$B$1:$AF$1&"",0)),0)} -> 0 | AB5: {=IFERROR(INDEX(PQ_Juli!$B$2:$AF$1048,MATCH($C5,PQ_Juli!$A$2:$A$1048,0),MATCH(AB$3&"",PQ_Juli!$B$1:$AF$1&"",0)),0)} -> 1 | AC5: {=IFERROR(INDEX(PQ_Juli!$B$2:$AF$1048,MATCH($C5,PQ_Juli!$A$2:$A$1048,0),MATCH(AC$3&"",PQ_Juli!$B$1:$AF$1&"",0)),0)} -> 0 | AD5: {=IFERROR(INDEX(PQ_Juli!$B$2:$AF$1048,MATCH($C5,PQ_Juli!$A$2:$A$1048,0),MATCH(AD$3&"",PQ_Juli!$B$1:$AF$1&"",0)),0)} -> 1 | AE5: {=IFERROR(INDEX(PQ_Juli!$B$2:$AF$1048,MATCH($C5,PQ_Juli!$A$2:$A$1048,0),MATCH(AE$3&"",PQ_Juli!$B$1:$AF$1&"",0)),0)} -> 0 | AF5: {=IFERROR(INDEX(PQ_Juli!$B$2:$AF$1048,MATCH($C5,PQ_Juli!$A$2:$A$1048,0),MATCH(AF$3&"",PQ_Juli!$B$1:$AF$1&"",0)),0)} -> 0 | AH5: {=IFERROR(INDEX(PQ_Juli!$B$2:$AF$1048,MATCH($C5,PQ_Juli!$A$2:$A$1048,0),MATCH(AH$3&"",PQ_Juli!$B$1:$AF$1&"",0)),0)} -> 0 | AI5: {=IFERROR(INDEX(PQ_Juli!$B$2:$AF$1048,MATCH($C5,PQ_Juli!$A$2:$A$1048,0),MATCH(AI$3&"",PQ_Juli!$B$1:$AF$1&"",0)),0)} -> 0 | AJ5: {=IFERROR(INDEX(PQ_Juli!$B$2:$AF$1048,MATCH($C5,PQ_Juli!$A$2:$A$1048,0),MATCH(AJ$3&"",PQ_Juli!$B$1:$AF$1&"",0)),0)} -> 0 | AK5: {=IFERROR(INDEX(PQ_Juli!$B$2:$AF$1048,MATCH($C5,PQ_Juli!$A$2:$A$1048,0),MATCH(AK$3&"",PQ_Juli!$B$1:$AF$1&"",0)),0)} -> 0 | AL5: {=IFERROR(INDEX(PQ_Juli!$B$2:$AF$1048,MATCH($C5,PQ_Juli!$A$2:$A$1048,0),MATCH(AL$3&"",PQ_Juli!$B$1:$AF$1&"",0)),0)} -> 0 | AM5: 3 | AN5: =SUM(H5:AL5)+AM5 -> 17 | AO5: =(G5-AN5)+AZ5 -> 68 | AP5: 20 | AQ5: Pcs | AR5: 46210 | AS5: 1 | AT5: 46232 | AU5: 1 | AV5: 46213 | AW5: 46234 | AX5: =IFERROR(IF(AV5="",0,$D5*AS5),0) -> 30 | AY5: =IFERROR(IF(AW5="",0,$D5*AU5),0) -> 30 | AZ5: =AX5+AY5 -> 60 | BA5: =(G5-AN5)+AZ5 -> 68 | BE5: Catatan : Kasih spare misal 10 sebelum mendekati buffer stock sudah muncul alarm | BN5: 37
A6: =AO6 -> #REF! | C6: Ca 125 | D6: 30 | E6: 41 | F6: 30 | G6: =#REF! -> #REF! | H6: {=IFERROR(INDEX(PQ_Juli!$B$2:$AF$1048,MATCH($C6,PQ_Juli!$A$2:$A$1048,0),MATCH(H$3&"",PQ_Juli!$B$1:$AF$1&"",0)),0)} -> 2 | I6: {=IFERROR(INDEX(PQ_Juli!$B$2:$AF$1048,MATCH($C6,PQ_Juli!$A$2:$A$1048,0),MATCH(I$3&"",PQ_Juli!$B$1:$AF$1&"",0)),0)} -> 0 | J6: {=IFERROR(INDEX(PQ_Juli!$B$2:$AF$1048,MATCH($C6,PQ_Juli!$A$2:$A$1048,0),MATCH(J$3&"",PQ_Juli!$B$1:$AF$1&"",0)),0)} -> 1 | K6: {=IFERROR(INDEX(PQ_Juli!$B$2:$AF$1048,MATCH($C6,PQ_Juli!$A$2:$A$1048,0),MATCH(K$3&"",PQ_Juli!$B$1:$AF$1&"",0)),0)} -> 1 | M6: {=IFERROR(INDEX(PQ_Juli!$B$2:$AF$1048,MATCH($C6,PQ_Juli!$A$2:$A$1048,0),MATCH(M$3&"",PQ_Juli!$B$1:$AF$1&"",0)),0)} -> 0 | N6: {=IFERROR(INDEX(PQ_Juli!$B$2:$AF$1048,MATCH($C6,PQ_Juli!$A$2:$A$1048,0),MATCH(N$3&"",PQ_Juli!$B$1:$AF$1&"",0)),0)} -> 0 | O6: {=IFERROR(INDEX(PQ_Juli!$B$2:$AF$1048,MATCH($C6,PQ_Juli!$A$2:$A$1048,0),MATCH(O$3&"",PQ_Juli!$B$1:$AF$1&"",0)),0)} -> 0 | P6: {=IFERROR(INDEX(PQ_Juli!$B$2:$AF$1048,MATCH($C6,PQ_Juli!$A$2:$A$1048,0),MATCH(P$3&"",PQ_Juli!$B$1:$AF$1&"",0)),0)} -> 0 | Q6: {=IFERROR(INDEX(PQ_Juli!$B$2:$AF$1048,MATCH($C6,PQ_Juli!$A$2:$A$1048,0),MATCH(Q$3&"",PQ_Juli!$B$1:$AF$1&"",0)),0)} -> 2 | R6: {=IFERROR(INDEX(PQ_Juli!$B$2:$AF$1048,MATCH($C6,PQ_Juli!$A$2:$A$1048,0),MATCH(R$3&"",PQ_Juli!$B$1:$AF$1&"",0)),0)} -> 0 | T6: {=IFERROR(INDEX(PQ_Juli!$B$2:$AF$1048,MATCH($C6,PQ_Juli!$A$2:$A$1048,0),MATCH(T$3&"",PQ_Juli!$B$1:$AF$1&"",0)),0)} -> 2 | U6: {=IFERROR(INDEX(PQ_Juli!$B$2:$AF$1048,MATCH($C6,PQ_Juli!$A$2:$A$1048,0),MATCH(U$3&"",PQ_Juli!$B$1:$AF$1&"",0)),0)} -> 0 | V6: {=IFERROR(INDEX(PQ_Juli!$B$2:$AF$1048,MATCH($C6,PQ_Juli!$A$2:$A$1048,0),MATCH(V$3&"",PQ_Juli!$B$1:$AF$1&"",0)),0)} -> 0 | W6: {=IFERROR(INDEX(PQ_Juli!$B$2:$AF$1048,MATCH($C6,PQ_Juli!$A$2:$A$1048,0),MATCH(W$3&"",PQ_Juli!$B$1:$AF$1&"",0)),0)} -> 2 | X6: {=IFERROR(INDEX(PQ_Juli!$B$2:$AF$1048,MATCH($C6,PQ_Juli!$A$2:$A$1048,0),MATCH(X$3&"",PQ_Juli!$B$1:$AF$1&"",0)),0)} -> 0 | Y6: {=IFERROR(INDEX(PQ_Juli!$B$2:$AF$1048,MATCH($C6,PQ_Juli!$A$2:$A$1048,0),MATCH(Y$3&"",PQ_Juli!$B$1:$AF$1&"",0)),0)} -> 0 | AA6: {=IFERROR(INDEX(PQ_Juli!$B$2:$AF$1048,MATCH($C6,PQ_Juli!$A$2:$A$1048,0),MATCH(AA$3&"",PQ_Juli!$B$1:$AF$1&"",0)),0)} -> 0 | AB6: {=IFERROR(INDEX(PQ_Juli!$B$2:$AF$1048,MATCH($C6,PQ_Juli!$A$2:$A$1048,0),MATCH(AB$3&"",PQ_Juli!$B$1:$AF$1&"",0)),0)} -> 1 | AC6: {=IFERROR(INDEX(PQ_Juli!$B$2:$AF$1048,MATCH($C6,PQ_Juli!$A$2:$A$1048,0),MATCH(AC$3&"",PQ_Juli!$B$1:$AF$1&"",0)),0)} -> 0 | AD6: {=IFERROR(INDEX(PQ_Juli!$B$2:$AF$1048,MATCH($C6,PQ_Juli!$A$2:$A$1048,0),MATCH(AD$3&"",PQ_Juli!$B$1:$AF$1&"",0)),0)} -> 0 | AE6: {=IFERROR(INDEX(PQ_Juli!$B$2:$AF$1048,MATCH($C6,PQ_Juli!$A$2:$A$1048,0),MATCH(AE$3&"",PQ_Juli!$B$1:$AF$1&"",0)),0)} -> 1 | AF6: {=IFERROR(INDEX(PQ_Juli!$B$2:$AF$1048,MATCH($C6,PQ_Juli!$A$2:$A$1048,0),MATCH(AF$3&"",PQ_Juli!$B$1:$AF$1&"",0)),0)} -> 0 | AH6: {=IFERROR(INDEX(PQ_Juli!$B$2:$AF$1048,MATCH($C6,PQ_Juli!$A$2:$A$1048,0),MATCH(AH$3&"",PQ_Juli!$B$1:$AF$1&"",0)),0)} -> 0 | AI6: {=IFERROR(INDEX(PQ_Juli!$B$2:$AF$1048,MATCH($C6,PQ_Juli!$A$2:$A$1048,0),MATCH(AI$3&"",PQ_Juli!$B$1:$AF$1&"",0)),0)} -> 1 | AJ6: {=IFERROR(INDEX(PQ_Juli!$B$2:$AF$1048,MATCH($C6,PQ_Juli!$A$2:$A$1048,0),MATCH(AJ$3&"",PQ_Juli!$B$1:$AF$1&"",0)),0)} -> 0 | AK6: {=IFERROR(INDEX(PQ_Juli!$B$2:$AF$1048,MATCH($C6,PQ_Juli!$A$2:$A$1048,0),MATCH(AK$3&"",PQ_Juli!$B$1:$AF$1&"",0)),0)} -> 0 | AL6: {=IFERROR(INDEX(PQ_Juli!$B$2:$AF$1048,MATCH($C6,PQ_Juli!$A$2:$A$1048,0),MATCH(AL$3&"",PQ_Juli!$B$1:$AF$1&"",0)),0)} -> 1 | AM6: 3 | AN6: =SUM(H6:AL6)+AM6 -> 17 | AO6: =(G6-AN6)+AZ6 -> #REF! | AP6: 20 | AQ6: Pcs | AX6: =IFERROR(IF(AV6="",0,$D6*AS6),0) -> 0 | AY6: =IFERROR(IF(AW6="",0,$D6*AU6),0) -> 0 | AZ6: =AX6+AY6 -> 0 | BA6: =(G6-AN6)+AZ6 -> #REF! | BN6: 46
A7: =AO7 -> #REF! | C7: Testosteron | D7: 30 | E7: 11 | F7: 15 | G7: =#REF! -> #REF! | H7: {=IFERROR(INDEX(PQ_Juli!$B$2:$AF$1048,MATCH($C7,PQ_Juli!$A$2:$A$1048,0),MATCH(H$3&"",PQ_Juli!$B$1:$AF$1&"",0)),0)} -> 0 | I7: {=IFERROR(INDEX(PQ_Juli!$B$2:$AF$1048,MATCH($C7,PQ_Juli!$A$2:$A$1048,0),MATCH(I$3&"",PQ_Juli!$B$1:$AF$1&"",0)),0)} -> 4 | J7: {=IFERROR(INDEX(PQ_Juli!$B$2:$AF$1048,MATCH($C7,PQ_Juli!$A$2:$A$1048,0),MATCH(J$3&"",PQ_Juli!$B$1:$AF$1&"",0)),0)} -> 0 | K7: {=IFERROR(INDEX(PQ_Juli!$B$2:$AF$1048,MATCH($C7,PQ_Juli!$A$2:$A$1048,0),MATCH(K$3&"",PQ_Juli!$B$1:$AF$1&"",0)),0)} -> 1 | M7: {=IFERROR(INDEX(PQ_Juli!$B$2:$AF$1048,MATCH($C7,PQ_Juli!$A$2:$A$1048,0),MATCH(M$3&"",PQ_Juli!$B$1:$AF$1&"",0)),0)} -> 1 | N7: {=IFERROR(INDEX(PQ_Juli!$B$2:$AF$1048,MATCH($C7,PQ_Juli!$A$2:$A$1048,0),MATCH(N$3&"",PQ_Juli!$B$1:$AF$1&"",0)),0)} -> 0 | O7: {=IFERROR(INDEX(PQ_Juli!$B$2:$AF$1048,MATCH($C7,PQ_Juli!$A$2:$A$1048,0),MATCH(O$3&"",PQ_Juli!$B$1:$AF$1&"",0)),0)} -> 0 | P7: {=IFERROR(INDEX(PQ_Juli!$B$2:$AF$1048,MATCH($C7,PQ_Juli!$A$2:$A$1048,0),MATCH(P$3&"",PQ_Juli!$B$1:$AF$1&"",0)),0)} -> 1 | Q7: {=IFERROR(INDEX(PQ_Juli!$B$2:$AF$1048,MATCH($C7,PQ_Juli!$A$2:$A$1048,0),MATCH(Q$3&"",PQ_Juli!$B$1:$AF$1&"",0)),0)} -> 0 | R7: {=IFERROR(INDEX(PQ_Juli!$B$2:$AF$1048,MATCH($C7,PQ_Juli!$A$2:$A$1048,0),MATCH(R$3&"",PQ_Juli!$B$1:$AF$1&"",0)),0)} -> 1 | T7: {=IFERROR(INDEX(PQ_Juli!$B$2:$AF$1048,MATCH($C7,PQ_Juli!$A$2:$A$1048,0),MATCH(T$3&"",PQ_Juli!$B$1:$AF$1&"",0)),0)} -> 2 | U7: {=IFERROR(INDEX(PQ_Juli!$B$2:$AF$1048,MATCH($C7,PQ_Juli!$A$2:$A$1048,0),MATCH(U$3&"",PQ_Juli!$B$1:$AF$1&"",0)),0)} -> 0 | V7: {=IFERROR(INDEX(PQ_Juli!$B$2:$AF$1048,MATCH($C7,PQ_Juli!$A$2:$A$1048,0),MATCH(V$3&"",PQ_Juli!$B$1:$AF$1&"",0)),0)} -> 3 | W7: {=IFERROR(INDEX(PQ_Juli!$B$2:$AF$1048,MATCH($C7,PQ_Juli!$A$2:$A$1048,0),MATCH(W$3&"",PQ_Juli!$B$1:$AF$1&"",0)),0)} -> 1 | X7: {=IFERROR(INDEX(PQ_Juli!$B$2:$AF$1048,MATCH($C7,PQ_Juli!$A$2:$A$1048,0),MATCH(X$3&"",PQ_Juli!$B$1:$AF$1&"",0)),0)} -> 4 | Y7: {=IFERROR(INDEX(PQ_Juli!$B$2:$AF$1048,MATCH($C7,PQ_Juli!$A$2:$A$1048,0),MATCH(Y$3&"",PQ_Juli!$B$1:$AF$1&"",0)),0)} -> 0 | AA7: {=IFERROR(INDEX(PQ_Juli!$B$2:$AF$1048,MATCH($C7,PQ_Juli!$A$2:$A$1048,0),MATCH(AA$3&"",PQ_Juli!$B$1:$AF$1&"",0)),0)} -> 2 | AB7: {=IFERROR(INDEX(PQ_Juli!$B$2:$AF$1048,MATCH($C7,PQ_Juli!$A$2:$A$1048,0),MATCH(AB$3&"",PQ_Juli!$B$1:$AF$1&"",0)),0)} -> 0 | AC7: {=IFERROR(INDEX(PQ_Juli!$B$2:$AF$1048,MATCH($C7,PQ_Juli!$A$2:$A$1048,0),MATCH(AC$3&"",PQ_Juli!$B$1:$AF$1&"",0)),0)} -> 1 | AD7: {=IFERROR(INDEX(PQ_Juli!$B$2:$AF$1048,MATCH($C7,PQ_Juli!$A$2:$A$1048,0),MATCH(AD$3&"",PQ_Juli!$B$1:$AF$1&"",0)),0)} -> 1 | AE7: {=IFERROR(INDEX(PQ_Juli!$B$2:$AF$1048,MATCH($C7,PQ_Juli!$A$2:$A$1048,0),MATCH(AE$3&"",PQ_Juli!$B$1:$AF$1&"",0)),0)} -> 0 | AF7: {=IFERROR(INDEX(PQ_Juli!$B$2:$AF$1048,MATCH($C7,PQ_Juli!$A$2:$A$1048,0),MATCH(AF$3&"",PQ_Juli!$B$1:$AF$1&"",0)),0)} -> 0 | AH7: {=IFERROR(INDEX(PQ_Juli!$B$2:$AF$1048,MATCH($C7,PQ_Juli!$A$2:$A$1048,0),MATCH(AH$3&"",PQ_Juli!$B$1:$AF$1&"",0)),0)} -> 2 | AI7: {=IFERROR(INDEX(PQ_Juli!$B$2:$AF$1048,MATCH($C7,PQ_Juli!$A$2:$A$1048,0),MATCH(AI$3&"",PQ_Juli!$B$1:$AF$1&"",0)),0)} -> 0 | AJ7: {=IFERROR(INDEX(PQ_Juli!$B$2:$AF$1048,MATCH($C7,PQ_Juli!$A$2:$A$1048,0),MATCH(AJ$3&"",PQ_Juli!$B$1:$AF$1&"",0)),0)} -> 0 | AK7: {=IFERROR(INDEX(PQ_Juli!$B$2:$AF$1048,MATCH($C7,PQ_Juli!$A$2:$A$1048,0),MATCH(AK$3&"",PQ_Juli!$B$1:$AF$1&"",0)),0)} -> 1 | AL7: {=IFERROR(INDEX(PQ_Juli!$B$2:$AF$1048,MATCH($C7,PQ_Juli!$A$2:$A$1048,0),MATCH(AL$3&"",PQ_Juli!$B$1:$AF$1&"",0)),0)} -> 2 | AM7: 3 | AN7: =SUM(H7:AL7)+AM7 -> 30 | AO7: =(G7-AN7)+AZ7 -> #REF! | AP7: 20 | AQ7: Pcs | AR7: 46225 | AS7: 1 | AV7: 46231 | AX7: =IFERROR(IF(AV7="",0,$D7*AS7),0) -> 30 | AY7: =IFERROR(IF(AW7="",0,$D7*AU7),0) -> 0 | AZ7: =AX7+AY7 -> 30 | BA7: =(G7-AN7)+AZ7 -> #REF! | BD7: Warna | BE7: Definisi Warna | BN7: 2
A8: =AO8 -> #REF! | C8: LH | D8: 60 | E8: 6 | F8: 10 | G8: =#REF! -> #REF! | H8: {=IFERROR(INDEX(PQ_Juli!$B$2:$AF$1048,MATCH($C8,PQ_Juli!$A$2:$A$1048,0),MATCH(H$3&"",PQ_Juli!$B$1:$AF$1&"",0)),0)} -> 0 | I8: {=IFERROR(INDEX(PQ_Juli!$B$2:$AF$1048,MATCH($C8,PQ_Juli!$A$2:$A$1048,0),MATCH(I$3&"",PQ_Juli!$B$1:$AF$1&"",0)),0)} -> 0 | J8: {=IFERROR(INDEX(PQ_Juli!$B$2:$AF$1048,MATCH($C8,PQ_Juli!$A$2:$A$1048,0),MATCH(J$3&"",PQ_Juli!$B$1:$AF$1&"",0)),0)} -> 0 | K8: {=IFERROR(INDEX(PQ_Juli!$B$2:$AF$1048,MATCH($C8,PQ_Juli!$A$2:$A$1048,0),MATCH(K$3&"",PQ_Juli!$B$1:$AF$1&"",0)),0)} -> 1 | M8: {=IFERROR(INDEX(PQ_Juli!$B$2:$AF$1048,MATCH($C8,PQ_Juli!$A$2:$A$1048,0),MATCH(M$3&"",PQ_Juli!$B$1:$AF$1&"",0)),0)} -> 0 | N8: {=IFERROR(INDEX(PQ_Juli!$B$2:$AF$1048,MATCH($C8,PQ_Juli!$A$2:$A$1048,0),MATCH(N$3&"",PQ_Juli!$B$1:$AF$1&"",0)),0)} -> 0 | O8: {=IFERROR(INDEX(PQ_Juli!$B$2:$AF$1048,MATCH($C8,PQ_Juli!$A$2:$A$1048,0),MATCH(O$3&"",PQ_Juli!$B$1:$AF$1&"",0)),0)} -> 0 | P8: {=IFERROR(INDEX(PQ_Juli!$B$2:$AF$1048,MATCH($C8,PQ_Juli!$A$2:$A$1048,0),MATCH(P$3&"",PQ_Juli!$B$1:$AF$1&"",0)),0)} -> 0 | Q8: {=IFERROR(INDEX(PQ_Juli!$B$2:$AF$1048,MATCH($C8,PQ_Juli!$A$2:$A$1048,0),MATCH(Q$3&"",PQ_Juli!$B$1:$AF$1&"",0)),0)} -> 1 | R8: {=IFERROR(INDEX(PQ_Juli!$B$2:$AF$1048,MATCH($C8,PQ_Juli!$A$2:$A$1048,0),MATCH(R$3&"",PQ_Juli!$B$1:$AF$1&"",0)),0)} -> 2 | T8: {=IFERROR(INDEX(PQ_Juli!$B$2:$AF$1048,MATCH($C8,PQ_Juli!$A$2:$A$1048,0),MATCH(T$3&"",PQ_Juli!$B$1:$AF$1&"",0)),0)} -> 1 | U8: {=IFERROR(INDEX(PQ_Juli!$B$2:$AF$1048,MATCH($C8,PQ_Juli!$A$2:$A$1048,0),MATCH(U$3&"",PQ_Juli!$B$1:$AF$1&"",0)),0)} -> 0 | V8: {=IFERROR(INDEX(PQ_Juli!$B$2:$AF$1048,MATCH($C8,PQ_Juli!$A$2:$A$1048,0),MATCH(V$3&"",PQ_Juli!$B$1:$AF$1&"",0)),0)} -> 2 | W8: {=IFERROR(INDEX(PQ_Juli!$B$2:$AF$1048,MATCH($C8,PQ_Juli!$A$2:$A$1048,0),MATCH(W$3&"",PQ_Juli!$B$1:$AF$1&"",0)),0)} -> 1 | X8: {=IFERROR(INDEX(PQ_Juli!$B$2:$AF$1048,MATCH($C8,PQ_Juli!$A$2:$A$1048,0),MATCH(X$3&"",PQ_Juli!$B$1:$AF$1&"",0)),0)} -> 2 | Y8: {=IFERROR(INDEX(PQ_Juli!$B$2:$AF$1048,MATCH($C8,PQ_Juli!$A$2:$A$1048,0),MATCH(Y$3&"",PQ_Juli!$B$1:$AF$1&"",0)),0)} -> 0 | AA8: {=IFERROR(INDEX(PQ_Juli!$B$2:$AF$1048,MATCH($C8,PQ_Juli!$A$2:$A$1048,0),MATCH(AA$3&"",PQ_Juli!$B$1:$AF$1&"",0)),0)} -> 1 | AB8: {=IFERROR(INDEX(PQ_Juli!$B$2:$AF$1048,MATCH($C8,PQ_Juli!$A$2:$A$1048,0),MATCH(AB$3&"",PQ_Juli!$B$1:$AF$1&"",0)),0)} -> 0 | AC8: {=IFERROR(INDEX(PQ_Juli!$B$2:$AF$1048,MATCH($C8,PQ_Juli!$A$2:$A$1048,0),MATCH(AC$3&"",PQ_Juli!$B$1:$AF$1&"",0)),0)} -> 3 | AD8: {=IFERROR(INDEX(PQ_Juli!$B$2:$AF$1048,MATCH($C8,PQ_Juli!$A$2:$A$1048,0),MATCH(AD$3&"",PQ_Juli!$B$1:$AF$1&"",0)),0)} -> 1 | AE8: {=IFERROR(INDEX(PQ_Juli!$B$2:$AF$1048,MATCH($C8,PQ_Juli!$A$2:$A$1048,0),MATCH(AE$3&"",PQ_Juli!$B$1:$AF$1&"",0)),0)} -> 0 | AF8: {=IFERROR(INDEX(PQ_Juli!$B$2:$AF$1048,MATCH($C8,PQ_Juli!$A$2:$A$1048,0),MATCH(AF$3&"",PQ_Juli!$B$1:$AF$1&"",0)),0)} -> 1 | AH8: {=IFERROR(INDEX(PQ_Juli!$B$2:$AF$1048,MATCH($C8,PQ_Juli!$A$2:$A$1048,0),MATCH(AH$3&"",PQ_Juli!$B$1:$AF$1&"",0)),0)} -> 0 | AI8: {=IFERROR(INDEX(PQ_Juli!$B$2:$AF$1048,MATCH($C8,PQ_Juli!$A$2:$A$1048,0),MATCH(AI$3&"",PQ_Juli!$B$1:$AF$1&"",0)),0)} -> 1 | AJ8: {=IFERROR(INDEX(PQ_Juli!$B$2:$AF$1048,MATCH($C8,PQ_Juli!$A$2:$A$1048,0),MATCH(AJ$3&"",PQ_Juli!$B$1:$AF$1&"",0)),0)} -> 0 | AK8: {=IFERROR(INDEX(PQ_Juli!$B$2:$AF$1048,MATCH($C8,PQ_Juli!$A$2:$A$1048,0),MATCH(AK$3&"",PQ_Juli!$B$1:$AF$1&"",0)),0)} -> 0 | AL8: {=IFERROR(INDEX(PQ_Juli!$B$2:$AF$1048,MATCH($C8,PQ_Juli!$A$2:$A$1048,0),MATCH(AL$3&"",PQ_Juli!$B$1:$AF$1&"",0)),0)} -> 1 | AM8: 3 | AN8: =SUM(H8:AL8)+AM8 -> 21 | AO8: =(G8-AN8)+AZ8 -> #REF! | AP8: 20 | AQ8: Pcs | AX8: =IFERROR(IF(AV8="",0,$D8*AS8),0) -> 0 | AY8: =IFERROR(IF(AW8="",0,$D8*AU8),0) -> 0 | AZ8: =AX8+AY8 -> 0 | BA8: =(G8-AN8)+AZ8 -> #REF! | BE8: Sudah mendekati Buffer Stock (Harus mulai dipesan barangnya) | BN8: 19
A9: =AO9 -> 63 | C9: FSH | D9: 60 | E9: 7 | F9: 14 | G9: 44 | H9: {=IFERROR(INDEX(PQ_Juli!$B$2:$AF$1048,MATCH($C9,PQ_Juli!$A$2:$A$1048,0),MATCH(H$3&"",PQ_Juli!$B$1:$AF$1&"",0)),0)} -> 0 | I9: {=IFERROR(INDEX(PQ_Juli!$B$2:$AF$1048,MATCH($C9,PQ_Juli!$A$2:$A$1048,0),MATCH(I$3&"",PQ_Juli!$B$1:$AF$1&"",0)),0)} -> 2 | J9: {=IFERROR(INDEX(PQ_Juli!$B$2:$AF$1048,MATCH($C9,PQ_Juli!$A$2:$A$1048,0),MATCH(J$3&"",PQ_Juli!$B$1:$AF$1&"",0)),0)} -> 1 | K9: {=IFERROR(INDEX(PQ_Juli!$B$2:$AF$1048,MATCH($C9,PQ_Juli!$A$2:$A$1048,0),MATCH(K$3&"",PQ_Juli!$B$1:$AF$1&"",0)),0)} -> 0 | M9: {=IFERROR(INDEX(PQ_Juli!$B$2:$AF$1048,MATCH($C9,PQ_Juli!$A$2:$A$1048,0),MATCH(M$3&"",PQ_Juli!$B$1:$AF$1&"",0)),0)} -> 1 | N9: {=IFERROR(INDEX(PQ_Juli!$B$2:$AF$1048,MATCH($C9,PQ_Juli!$A$2:$A$1048,0),MATCH(N$3&"",PQ_Juli!$B$1:$AF$1&"",0)),0)} -> 2 | O9: {=IFERROR(INDEX(PQ_Juli!$B$2:$AF$1048,MATCH($C9,PQ_Juli!$A$2:$A$1048,0),MATCH(O$3&"",PQ_Juli!$B$1:$AF$1&"",0)),0)} -> 0 | P9: {=IFERROR(INDEX(PQ_Juli!$B$2:$AF$1048,MATCH($C9,PQ_Juli!$A$2:$A$1048,0),MATCH(P$3&"",PQ_Juli!$B$1:$AF$1&"",0)),0)} -> 0 | Q9: {=IFERROR(INDEX(PQ_Juli!$B$2:$AF$1048,MATCH($C9,PQ_Juli!$A$2:$A$1048,0),MATCH(Q$3&"",PQ_Juli!$B$1:$AF$1&"",0)),0)} -> 1 | R9: {=IFERROR(INDEX(PQ_Juli!$B$2:$AF$1048,MATCH($C9,PQ_Juli!$A$2:$A$1048,0),MATCH(R$3&"",PQ_Juli!$B$1:$AF$1&"",0)),0)} -> 3 | T9: {=IFERROR(INDEX(PQ_Juli!$B$2:$AF$1048,MATCH($C9,PQ_Juli!$A$2:$A$1048,0),MATCH(T$3&"",PQ_Juli!$B$1:$AF$1&"",0)),0)} -> 2 | U9: {=IFERROR(INDEX(PQ_Juli!$B$2:$AF$1048,MATCH($C9,PQ_Juli!$A$2:$A$1048,0),MATCH(U$3&"",PQ_Juli!$B$1:$AF$1&"",0)),0)} -> 2 | V9: {=IFERROR(INDEX(PQ_Juli!$B$2:$AF$1048,MATCH($C9,PQ_Juli!$A$2:$A$1048,0),MATCH(V$3&"",PQ_Juli!$B$1:$AF$1&"",0)),0)} -> 4 | W9: {=IFERROR(INDEX(PQ_Juli!$B$2:$AF$1048,MATCH($C9,PQ_Juli!$A$2:$A$1048,0),MATCH(W$3&"",PQ_Juli!$B$1:$AF$1&"",0)),0)} -> 1 | X9: {=IFERROR(INDEX(PQ_Juli!$B$2:$AF$1048,MATCH($C9,PQ_Juli!$A$2:$A$1048,0),MATCH(X$3&"",PQ_Juli!$B$1:$AF$1&"",0)),0)} -> 1 | Y9: {=IFERROR(INDEX(PQ_Juli!$B$2:$AF$1048,MATCH($C9,PQ_Juli!$A$2:$A$1048,0),MATCH(Y$3&"",PQ_Juli!$B$1:$AF$1&"",0)),0)} -> 0 | AA9: {=IFERROR(INDEX(PQ_Juli!$B$2:$AF$1048,MATCH($C9,PQ_Juli!$A$2:$A$1048,0),MATCH(AA$3&"",PQ_Juli!$B$1:$AF$1&"",0)),0)} -> 1 | AB9: {=IFERROR(INDEX(PQ_Juli!$B$2:$AF$1048,MATCH($C9,PQ_Juli!$A$2:$A$1048,0),MATCH(AB$3&"",PQ_Juli!$B$1:$AF$1&"",0)),0)} -> 2 | AC9: {=IFERROR(INDEX(PQ_Juli!$B$2:$AF$1048,MATCH($C9,PQ_Juli!$A$2:$A$1048,0),MATCH(AC$3&"",PQ_Juli!$B$1:$AF$1&"",0)),0)} -> 2 | AD9: {=IFERROR(INDEX(PQ_Juli!$B$2:$AF$1048,MATCH($C9,PQ_Juli!$A$2:$A$1048,0),MATCH(AD$3&"",PQ_Juli!$B$1:$AF$1&"",0)),0)} -> 0 | AE9: {=IFERROR(INDEX(PQ_Juli!$B$2:$AF$1048,MATCH($C9,PQ_Juli!$A$2:$A$1048,0),MATCH(AE$3&"",PQ_Juli!$B$1:$AF$1&"",0)),0)} -> 2 | AF9: {=IFERROR(INDEX(PQ_Juli!$B$2:$AF$1048,MATCH($C9,PQ_Juli!$A$2:$A$1048,0),MATCH(AF$3&"",PQ_Juli!$B$1:$AF$1&"",0)),0)} -> 0 | AH9: {=IFERROR(INDEX(PQ_Juli!$B$2:$AF$1048,MATCH($C9,PQ_Juli!$A$2:$A$1048,0),MATCH(AH$3&"",PQ_Juli!$B$1:$AF$1&"",0)),0)} -> 2 | AI9: {=IFERROR(INDEX(PQ_Juli!$B$2:$AF$1048,MATCH($C9,PQ_Juli!$A$2:$A$1048,0),MATCH(AI$3&"",PQ_Juli!$B$1:$AF$1&"",0)),0)} -> 1 | AJ9: {=IFERROR(INDEX(PQ_Juli!$B$2:$AF$1048,MATCH($C9,PQ_Juli!$A$2:$A$1048,0),MATCH(AJ$3&"",PQ_Juli!$B$1:$AF$1&"",0)),0)} -> 1 | AK9: {=IFERROR(INDEX(PQ_Juli!$B$2:$AF$1048,MATCH($C9,PQ_Juli!$A$2:$A$1048,0),MATCH(AK$3&"",PQ_Juli!$B$1:$AF$1&"",0)),0)} -> 1 | AL9: {=IFERROR(INDEX(PQ_Juli!$B$2:$AF$1048,MATCH($C9,PQ_Juli!$A$2:$A$1048,0),MATCH(AL$3&"",PQ_Juli!$B$1:$AF$1&"",0)),0)} -> 3 | AM9: 6 | AN9: =SUM(H9:AL9)+AM9 -> 41 | AO9: =(G9-AN9)+AZ9 -> 63 | AP9: 20 | AQ9: Pcs | AR9: 46219 | AS9: 1 | AV9: 46231 | AX9: =IFERROR(IF(AV9="",0,$D9*AS9),0) -> 60 | AY9: =IFERROR(IF(AW9="",0,$D9*AU9),0) -> 0 | AZ9: =AX9+AY9 -> 60 | BA9: =(G9-AN9)+AZ9 -> 63 | BE9: Dibawah Buffer Stock (CITO untuk pemesanan barangnya) | BN9: 4
A10: =AO10 -> 34 | C10: T3 Total | D10: 60 | E10: 21 | F10: 17 | G10: 64 | H10: {=IFERROR(INDEX(PQ_Juli!$B$2:$AF$1048,MATCH($C10,PQ_Juli!$A$2:$A$1048,0),MATCH(H$3&"",PQ_Juli!$B$1:$AF$1&"",0)),0)} -> 0 | I10: {=IFERROR(INDEX(PQ_Juli!$B$2:$AF$1048,MATCH($C10,PQ_Juli!$A$2:$A$1048,0),MATCH(I$3&"",PQ_Juli!$B$1:$AF$1&"",0)),0)} -> 0 | J10: 0 | K10: {=IFERROR(INDEX(PQ_Juli!$B$2:$AF$1048,MATCH($C10,PQ_Juli!$A$2:$A$1048,0),MATCH(K$3&"",PQ_Juli!$B$1:$AF$1&"",0)),0)} -> 1 | M10: 0 | N10: {=IFERROR(INDEX(PQ_Juli!$B$2:$AF$1048,MATCH($C10,PQ_Juli!$A$2:$A$1048,0),MATCH(N$3&"",PQ_Juli!$B$1:$AF$1&"",0)),0)} -> 3 | O10: {=IFERROR(INDEX(PQ_Juli!$B$2:$AF$1048,MATCH($C10,PQ_Juli!$A$2:$A$1048,0),MATCH(O$3&"",PQ_Juli!$B$1:$AF$1&"",0)),0)} -> 3 | P10: {=IFERROR(INDEX(PQ_Juli!$B$2:$AF$1048,MATCH($C10,PQ_Juli!$A$2:$A$1048,0),MATCH(P$3&"",PQ_Juli!$B$1:$AF$1&"",0)),0)} -> 0 | Q10: {=IFERROR(INDEX(PQ_Juli!$B$2:$AF$1048,MATCH($C10,PQ_Juli!$A$2:$A$1048,0),MATCH(Q$3&"",PQ_Juli!$B$1:$AF$1&"",0)),0)} -> 1 | R10: {=IFERROR(INDEX(PQ_Juli!$B$2:$AF$1048,MATCH($C10,PQ_Juli!$A$2:$A$1048,0),MATCH(R$3&"",PQ_Juli!$B$1:$AF$1&"",0)),0)} -> 0 | T10: {=IFERROR(INDEX(PQ_Juli!$B$2:$AF$1048,MATCH($C10,PQ_Juli!$A$2:$A$1048,0),MATCH(T$3&"",PQ_Juli!$B$1:$AF$1&"",0)),0)} -> 2 | U10: {=IFERROR(INDEX(PQ_Juli!$B$2:$AF$1048,MATCH($C10,PQ_Juli!$A$2:$A$1048,0),MATCH(U$3&"",PQ_Juli!$B$1:$AF$1&"",0)),0)} -> 0 | V10: {=IFERROR(INDEX(PQ_Juli!$B$2:$AF$1048,MATCH($C10,PQ_Juli!$A$2:$A$1048,0),MATCH(V$3&"",PQ_Juli!$B$1:$AF$1&"",0)),0)} -> 0 | W10: {=IFERROR(INDEX(PQ_Juli!$B$2:$AF$1048,MATCH($C10,PQ_Juli!$A$2:$A$1048,0),MATCH(W$3&"",PQ_Juli!$B$1:$AF$1&"",0)),0)} -> 2 | X10: {=IFERROR(INDEX(PQ_Juli!$B$2:$AF$1048,MATCH($C10,PQ_Juli!$A$2:$A$1048,0),MATCH(X$3&"",PQ_Juli!$B$1:$AF$1&"",0)),0)} -> 0 | Y10: {=IFERROR(INDEX(PQ_Juli!$B$2:$AF$1048,MATCH($C10,PQ_Juli!$A$2:$A$1048,0),MATCH(Y$3&"",PQ_Juli!$B$1:$AF$1&"",0)),0)} -> 1 | AA10: {=IFERROR(INDEX(PQ_Juli!$B$2:$AF$1048,MATCH($C10,PQ_Juli!$A$2:$A$1048,0),MATCH(AA$3&"",PQ_Juli!$B$1:$AF$1&"",0)),0)} -> 1 | AB10: {=IFERROR(INDEX(PQ_Juli!$B$2:$AF$1048,MATCH($C10,PQ_Juli!$A$2:$A$1048,0),MATCH(AB$3&"",PQ_Juli!$B$1:$AF$1&"",0)),0)} -> 3 | AC10: {=IFERROR(INDEX(PQ_Juli!$B$2:$AF$1048,MATCH($C10,PQ_Juli!$A$2:$A$1048,0),MATCH(AC$3&"",PQ_Juli!$B$1:$AF$1&"",0)),0)} -> 2 | AD10: {=IFERROR(INDEX(PQ_Juli!$B$2:$AF$1048,MATCH($C10,PQ_Juli!$A$2:$A$1048,0),MATCH(AD$3&"",PQ_Juli!$B$1:$AF$1&"",0)),0)} -> 0 | AE10: {=IFERROR(INDEX(PQ_Juli!$B$2:$AF$1048,MATCH($C10,PQ_Juli!$A$2:$A$1048,0),MATCH(AE$3&"",PQ_Juli!$B$1:$AF$1&"",0)),0)} -> 1 | AF10: {=IFERROR(INDEX(PQ_Juli!$B$2:$AF$1048,MATCH($C10,PQ_Juli!$A$2:$A$1048,0),MATCH(AF$3&"",PQ_Juli!$B$1:$AF$1&"",0)),0)} -> 0 | AH10: {=IFERROR(INDEX(PQ_Juli!$B$2:$AF$1048,MATCH($C10,PQ_Juli!$A$2:$A$1048,0),MATCH(AH$3&"",PQ_Juli!$B$1:$AF$1&"",0)),0)} -> 1 | AI10: 4 | AJ10: {=IFERROR(INDEX(PQ_Juli!$B$2:$AF$1048,MATCH($C10,PQ_Juli!$A$2:$A$1048,0),MATCH(AJ$3&"",PQ_Juli!$B$1:$AF$1&"",0)),0)} -> 0 | AK10: {=IFERROR(INDEX(PQ_Juli!$B$2:$AF$1048,MATCH($C10,PQ_Juli!$A$2:$A$1048,0),MATCH(AK$3&"",PQ_Juli!$B$1:$AF$1&"",0)),0)} -> 0 | AL10: {=IFERROR(INDEX(PQ_Juli!$B$2:$AF$1048,MATCH($C10,PQ_Juli!$A$2:$A$1048,0),MATCH(AL$3&"",PQ_Juli!$B$1:$AF$1&"",0)),0)} -> 1 | AM10: 4 | AN10: =SUM(H10:AL10)+AM10 -> 30 | AO10: =(G10-AN10)+AZ10 -> 34 | AP10: 30 | AQ10: Pcs | AX10: =IFERROR(IF(AV10="",0,$D10*AS10),0) -> 0 | AY10: =IFERROR(IF(AW10="",0,$D10*AU10),0) -> 0 | AZ10: =AX10+AY10 -> 0 | BA10: =(G10-AN10)+AZ10 -> 34 | BE10: Tanggal terakhir input data QC all reagen | BN10: 82
A11: =AO11 -> 76 | C11: T4 Total | D11: 60 | E11: 19 | F11: 12 | G11: 44 | H11: {=IFERROR(INDEX(PQ_Juli!$B$2:$AF$1048,MATCH($C11,PQ_Juli!$A$2:$A$1048,0),MATCH(H$3&"",PQ_Juli!$B$1:$AF$1&"",0)),0)} -> 0 | I11: {=IFERROR(INDEX(PQ_Juli!$B$2:$AF$1048,MATCH($C11,PQ_Juli!$A$2:$A$1048,0),MATCH(I$3&"",PQ_Juli!$B$1:$AF$1&"",0)),0)} -> 0 | J11: 0 | K11: {=IFERROR(INDEX(PQ_Juli!$B$2:$AF$1048,MATCH($C11,PQ_Juli!$A$2:$A$1048,0),MATCH(K$3&"",PQ_Juli!$B$1:$AF$1&"",0)),0)} -> 0 | M11: 0 | N11: {=IFERROR(INDEX(PQ_Juli!$B$2:$AF$1048,MATCH($C11,PQ_Juli!$A$2:$A$1048,0),MATCH(N$3&"",PQ_Juli!$B$1:$AF$1&"",0)),0)} -> 3 | O11: {=IFERROR(INDEX(PQ_Juli!$B$2:$AF$1048,MATCH($C11,PQ_Juli!$A$2:$A$1048,0),MATCH(O$3&"",PQ_Juli!$B$1:$AF$1&"",0)),0)} -> 3 | P11: {=IFERROR(INDEX(PQ_Juli!$B$2:$AF$1048,MATCH($C11,PQ_Juli!$A$2:$A$1048,0),MATCH(P$3&"",PQ_Juli!$B$1:$AF$1&"",0)),0)} -> 0 | Q11: {=IFERROR(INDEX(PQ_Juli!$B$2:$AF$1048,MATCH($C11,PQ_Juli!$A$2:$A$1048,0),MATCH(Q$3&"",PQ_Juli!$B$1:$AF$1&"",0)),0)} -> 1 | R11: {=IFERROR(INDEX(PQ_Juli!$B$2:$AF$1048,MATCH($C11,PQ_Juli!$A$2:$A$1048,0),MATCH(R$3&"",PQ_Juli!$B$1:$AF$1&"",0)),0)} -> 0 | T11: {=IFERROR(INDEX(PQ_Juli!$B$2:$AF$1048,MATCH($C11,PQ_Juli!$A$2:$A$1048,0),MATCH(T$3&"",PQ_Juli!$B$1:$AF$1&"",0)),0)} -> 2 | U11: {=IFERROR(INDEX(PQ_Juli!$B$2:$AF$1048,MATCH($C11,PQ_Juli!$A$2:$A$1048,0),MATCH(U$3&"",PQ_Juli!$B$1:$AF$1&"",0)),0)} -> 0 | V11: {=IFERROR(INDEX(PQ_Juli!$B$2:$AF$1048,MATCH($C11,PQ_Juli!$A$2:$A$1048,0),MATCH(V$3&"",PQ_Juli!$B$1:$AF$1&"",0)),0)} -> 0 | W11: {=IFERROR(INDEX(PQ_Juli!$B$2:$AF$1048,MATCH($C11,PQ_Juli!$A$2:$A$1048,0),MATCH(W$3&"",PQ_Juli!$B$1:$AF$1&"",0)),0)} -> 2 | X11: {=IFERROR(INDEX(PQ_Juli!$B$2:$AF$1048,MATCH($C11,PQ_Juli!$A$2:$A$1048,0),MATCH(X$3&"",PQ_Juli!$B$1:$AF$1&"",0)),0)} -> 0 | Y11: {=IFERROR(INDEX(PQ_Juli!$B$2:$AF$1048,MATCH($C11,PQ_Juli!$A$2:$A$1048,0),MATCH(Y$3&"",PQ_Juli!$B$1:$AF$1&"",0)),0)} -> 1 | AA11: {=IFERROR(INDEX(PQ_Juli!$B$2:$AF$1048,MATCH($C11,PQ_Juli!$A$2:$A$1048,0),MATCH(AA$3&"",PQ_Juli!$B$1:$AF$1&"",0)),0)} -> 1 | AB11: {=IFERROR(INDEX(PQ_Juli!$B$2:$AF$1048,MATCH($C11,PQ_Juli!$A$2:$A$1048,0),MATCH(AB$3&"",PQ_Juli!$B$1:$AF$1&"",0)),0)} -> 4 | AC11: {=IFERROR(INDEX(PQ_Juli!$B$2:$AF$1048,MATCH($C11,PQ_Juli!$A$2:$A$1048,0),MATCH(AC$3&"",PQ_Juli!$B$1:$AF$1&"",0)),0)} -> 2 | AD11: {=IFERROR(INDEX(PQ_Juli!$B$2:$AF$1048,MATCH($C11,PQ_Juli!$A$2:$A$1048,0),MATCH(AD$3&"",PQ_Juli!$B$1:$AF$1&"",0)),0)} -> 0 | AE11: {=IFERROR(INDEX(PQ_Juli!$B$2:$AF$1048,MATCH($C11,PQ_Juli!$A$2:$A$1048,0),MATCH(AE$3&"",PQ_Juli!$B$1:$AF$1&"",0)),0)} -> 1 | AF11: {=IFERROR(INDEX(PQ_Juli!$B$2:$AF$1048,MATCH($C11,PQ_Juli!$A$2:$A$1048,0),MATCH(AF$3&"",PQ_Juli!$B$1:$AF$1&"",0)),0)} -> 0 | AH11: {=IFERROR(INDEX(PQ_Juli!$B$2:$AF$1048,MATCH($C11,PQ_Juli!$A$2:$A$1048,0),MATCH(AH$3&"",PQ_Juli!$B$1:$AF$1&"",0)),0)} -> 0 | AI11: 4 | AJ11: {=IFERROR(INDEX(PQ_Juli!$B$2:$AF$1048,MATCH($C11,PQ_Juli!$A$2:$A$1048,0),MATCH(AJ$3&"",PQ_Juli!$B$1:$AF$1&"",0)),0)} -> 0 | AK11: {=IFERROR(INDEX(PQ_Juli!$B$2:$AF$1048,MATCH($C11,PQ_Juli!$A$2:$A$1048,0),MATCH(AK$3&"",PQ_Juli!$B$1:$AF$1&"",0)),0)} -> 0 | AL11: {=IFERROR(INDEX(PQ_Juli!$B$2:$AF$1048,MATCH($C11,PQ_Juli!$A$2:$A$1048,0),MATCH(AL$3&"",PQ_Juli!$B$1:$AF$1&"",0)),0)} -> 1 | AM11: 3 | AN11: =SUM(H11:AL11)+AM11 -> 28 | AO11: =(G11-AN11)+AZ11 -> 76 | AP11: 30 | AQ11: Pcs | AR11: 46225 | AS11: 1 | AV11: 46231 | AX11: =IFERROR(IF(AV11="",0,$D11*AS11),0) -> 60 | AY11: =IFERROR(IF(AW11="",0,$D11*AU11),0) -> 0 | AZ11: =AX11+AY11 -> 60 | BA11: =(G11-AN11)+AZ11 -> 76 | BD11: Buffer Stock adalah 30 % penambahan dari average sampel setiap bulan dalam 1 tahun | BN11: 66
A12: =AO12 -> 85 | C12: TSH | D12: 60 | E12: 14 | F12: 29 | G12: 92 | H12: {=IFERROR(INDEX(PQ_Juli!$B$2:$AF$1048,MATCH($C12,PQ_Juli!$A$2:$A$1048,0),MATCH(H$3&"",PQ_Juli!$B$1:$AF$1&"",0)),0)} -> 2 | I12: {=IFERROR(INDEX(PQ_Juli!$B$2:$AF$1048,MATCH($C12,PQ_Juli!$A$2:$A$1048,0),MATCH(I$3&"",PQ_Juli!$B$1:$AF$1&"",0)),0)} -> 1 | J12: {=IFERROR(INDEX(PQ_Juli!$B$2:$AF$1048,MATCH($C12,PQ_Juli!$A$2:$A$1048,0),MATCH(J$3&"",PQ_Juli!$B$1:$AF$1&"",0)),0)} -> 3 | K12: {=IFERROR(INDEX(PQ_Juli!$B$2:$AF$1048,MATCH($C12,PQ_Juli!$A$2:$A$1048,0),MATCH(K$3&"",PQ_Juli!$B$1:$AF$1&"",0)),0)} -> 0 | M12: 1 | N12: {=IFERROR(INDEX(PQ_Juli!$B$2:$AF$1048,MATCH($C12,PQ_Juli!$A$2:$A$1048,0),MATCH(N$3&"",PQ_Juli!$B$1:$AF$1&"",0)),0)} -> 2 | O12: {=IFERROR(INDEX(PQ_Juli!$B$2:$AF$1048,MATCH($C12,PQ_Juli!$A$2:$A$1048,0),MATCH(O$3&"",PQ_Juli!$B$1:$AF$1&"",0)),0)} -> 6 | P12: {=IFERROR(INDEX(PQ_Juli!$B$2:$AF$1048,MATCH($C12,PQ_Juli!$A$2:$A$1048,0),MATCH(P$3&"",PQ_Juli!$B$1:$AF$1&"",0)),0)} -> 1 | Q12: {=IFERROR(INDEX(PQ_Juli!$B$2:$AF$1048,MATCH($C12,PQ_Juli!$A$2:$A$1048,0),MATCH(Q$3&"",PQ_Juli!$B$1:$AF$1&"",0)),0)} -> 4 | R12: {=IFERROR(INDEX(PQ_Juli!$B$2:$AF$1048,MATCH($C12,PQ_Juli!$A$2:$A$1048,0),MATCH(R$3&"",PQ_Juli!$B$1:$AF$1&"",0)),0)} -> 0 | T12: {=IFERROR(INDEX(PQ_Juli!$B$2:$AF$1048,MATCH($C12,PQ_Juli!$A$2:$A$1048,0),MATCH(T$3&"",PQ_Juli!$B$1:$AF$1&"",0)),0)} -> 4 | U12: {=IFERROR(INDEX(PQ_Juli!$B$2:$AF$1048,MATCH($C12,PQ_Juli!$A$2:$A$1048,0),MATCH(U$3&"",PQ_Juli!$B$1:$AF$1&"",0)),0)} -> 1 | V12: {=IFERROR(INDEX(PQ_Juli!$B$2:$AF$1048,MATCH($C12,PQ_Juli!$A$2:$A$1048,0),MATCH(V$3&"",PQ_Juli!$B$1:$AF$1&"",0)),0)} -> 0 | W12: {=IFERROR(INDEX(PQ_Juli!$B$2:$AF$1048,MATCH($C12,PQ_Juli!$A$2:$A$1048,0),MATCH(W$3&"",PQ_Juli!$B$1:$AF$1&"",0)),0)} -> 3 | X12: {=IFERROR(INDEX(PQ_Juli!$B$2:$AF$1048,MATCH($C12,PQ_Juli!$A$2:$A$1048,0),MATCH(X$3&"",PQ_Juli!$B$1:$AF$1&"",0)),0)} -> 0 | Y12: {=IFERROR(INDEX(PQ_Juli!$B$2:$AF$1048,MATCH($C12,PQ_Juli!$A$2:$A$1048,0),MATCH(Y$3&"",PQ_Juli!$B$1:$AF$1&"",0)),0)} -> 1 | AA12: {=IFERROR(INDEX(PQ_Juli!$B$2:$AF$1048,MATCH($C12,PQ_Juli!$A$2:$A$1048,0),MATCH(AA$3&"",PQ_Juli!$B$1:$AF$1&"",0)),0)} -> 1 | AB12: {=IFERROR(INDEX(PQ_Juli!$B$2:$AF$1048,MATCH($C12,PQ_Juli!$A$2:$A$1048,0),MATCH(AB$3&"",PQ_Juli!$B$1:$AF$1&"",0)),0)} -> 7 | AC12: {=IFERROR(INDEX(PQ_Juli!$B$2:$AF$1048,MATCH($C12,PQ_Juli!$A$2:$A$1048,0),MATCH(AC$3&"",PQ_Juli!$B$1:$AF$1&"",0)),0)} -> 3 | AD12: {=IFERROR(INDEX(PQ_Juli!$B$2:$AF$1048,MATCH($C12,PQ_Juli!$A$2:$A$1048,0),MATCH(AD$3&"",PQ_Juli!$B$1:$AF$1&"",0)),0)} -> 4 | AE12: {=IFERROR(INDEX(PQ_Juli!$B$2:$AF$1048,MATCH($C12,PQ_Juli!$A$2:$A$1048,0),MATCH(AE$3&"",PQ_Juli!$B$1:$AF$1&"",0)),0)} -> 4 | AF12: {=IFERROR(INDEX(PQ_Juli!$B$2:$AF$1048,MATCH($C12,PQ_Juli!$A$2:$A$1048,0),MATCH(AF$3&"",PQ_Juli!$B$1:$AF$1&"",0)),0)} -> 10 | AH12: {=IFERROR(INDEX(PQ_Juli!$B$2:$AF$1048,MATCH($C12,PQ_Juli!$A$2:$A$1048,0),MATCH(AH$3&"",PQ_Juli!$B$1:$AF$1&"",0)),0)} -> 0 | AI12: 4 | AJ12: {=IFERROR(INDEX(PQ_Juli!$B$2:$AF$1048,MATCH($C12,PQ_Juli!$A$2:$A$1048,0),MATCH(AJ$3&"",PQ_Juli!$B$1:$AF$1&"",0)),0)} -> 1 | AK12: {=IFERROR(INDEX(PQ_Juli!$B$2:$AF$1048,MATCH($C12,PQ_Juli!$A$2:$A$1048,0),MATCH(AK$3&"",PQ_Juli!$B$1:$AF$1&"",0)),0)} -> 1 | AL12: {=IFERROR(INDEX(PQ_Juli!$B$2:$AF$1048,MATCH($C12,PQ_Juli!$A$2:$A$1048,0),MATCH(AL$3&"",PQ_Juli!$B$1:$AF$1&"",0)),0)} -> 3 | AN12: =SUM(H12:AL12)+AM12 -> 67 | AO12: =(G12-AN12)+AZ12 -> 85 | AP12: 40 | AQ12: Pcs | AR12: 46232 | AS12: 1 | AV12: 46234 | AX12: =IFERROR(IF(AV12="",0,$D12*AS12),0) -> 60 | AY12: =IFERROR(IF(AW12="",0,$D12*AU12),0) -> 0 | AZ12: =AX12+AY12 -> 60 | BA12: =(G12-AN12)+AZ12 -> 85 | BN12: 82
A13: =AO13 -> 90 | C13: FT4 | D13: 60 | E13: 29 | F13: 33 | G13: 44 | H13: {=IFERROR(INDEX(PQ_Juli!$B$2:$AF$1048,MATCH($C13,PQ_Juli!$A$2:$A$1048,0),MATCH(H$3&"",PQ_Juli!$B$1:$AF$1&"",0)),0)} -> 3 | I13: {=IFERROR(INDEX(PQ_Juli!$B$2:$AF$1048,MATCH($C13,PQ_Juli!$A$2:$A$1048,0),MATCH(I$3&"",PQ_Juli!$B$1:$AF$1&"",0)),0)} -> 3 | J13: {=IFERROR(INDEX(PQ_Juli!$B$2:$AF$1048,MATCH($C13,PQ_Juli!$A$2:$A$1048,0),MATCH(J$3&"",PQ_Juli!$B$1:$AF$1&"",0)),0)} -> 1 | K13: {=IFERROR(INDEX(PQ_Juli!$B$2:$AF$1048,MATCH($C13,PQ_Juli!$A$2:$A$1048,0),MATCH(K$3&"",PQ_Juli!$B$1:$AF$1&"",0)),0)} -> 5 | M13: {=IFERROR(INDEX(PQ_Juli!$B$2:$AF$1048,MATCH($C13,PQ_Juli!$A$2:$A$1048,0),MATCH(M$3&"",PQ_Juli!$B$1:$AF$1&"",0)),0)} -> 1 | N13: {=IFERROR(INDEX(PQ_Juli!$B$2:$AF$1048,MATCH($C13,PQ_Juli!$A$2:$A$1048,0),MATCH(N$3&"",PQ_Juli!$B$1:$AF$1&"",0)),0)} -> 1 | O13: {=IFERROR(INDEX(PQ_Juli!$B$2:$AF$1048,MATCH($C13,PQ_Juli!$A$2:$A$1048,0),MATCH(O$3&"",PQ_Juli!$B$1:$AF$1&"",0)),0)} -> 5 | P13: {=IFERROR(INDEX(PQ_Juli!$B$2:$AF$1048,MATCH($C13,PQ_Juli!$A$2:$A$1048,0),MATCH(P$3&"",PQ_Juli!$B$1:$AF$1&"",0)),0)} -> 1 | Q13: {=IFERROR(INDEX(PQ_Juli!$B$2:$AF$1048,MATCH($C13,PQ_Juli!$A$2:$A$1048,0),MATCH(Q$3&"",PQ_Juli!$B$1:$AF$1&"",0)),0)} -> 4 | R13: {=IFERROR(INDEX(PQ_Juli!$B$2:$AF$1048,MATCH($C13,PQ_Juli!$A$2:$A$1048,0),MATCH(R$3&"",PQ_Juli!$B$1:$AF$1&"",0)),0)} -> 5 | T13: {=IFERROR(INDEX(PQ_Juli!$B$2:$AF$1048,MATCH($C13,PQ_Juli!$A$2:$A$1048,0),MATCH(T$3&"",PQ_Juli!$B$1:$AF$1&"",0)),0)} -> 4 | U13: {=IFERROR(INDEX(PQ_Juli!$B$2:$AF$1048,MATCH($C13,PQ_Juli!$A$2:$A$1048,0),MATCH(U$3&"",PQ_Juli!$B$1:$AF$1&"",0)),0)} -> 5 | V13: {=IFERROR(INDEX(PQ_Juli!$B$2:$AF$1048,MATCH($C13,PQ_Juli!$A$2:$A$1048,0),MATCH(V$3&"",PQ_Juli!$B$1:$AF$1&"",0)),0)} -> 7 | W13: {=IFERROR(INDEX(PQ_Juli!$B$2:$AF$1048,MATCH($C13,PQ_Juli!$A$2:$A$1048,0),MATCH(W$3&"",PQ_Juli!$B$1:$AF$1&"",0)),0)} -> 0 | X13: {=IFERROR(INDEX(PQ_Juli!$B$2:$AF$1048,MATCH($C13,PQ_Juli!$A$2:$A$1048,0),MATCH(X$3&"",PQ_Juli!$B$1:$AF$1&"",0)),0)} -> 1 | Y13: {=IFERROR(INDEX(PQ_Juli!$B$2:$AF$1048,MATCH($C13,PQ_Juli!$A$2:$A$1048,0),MATCH(Y$3&"",PQ_Juli!$B$1:$AF$1&"",0)),0)} -> 5 | AA13: {=IFERROR(INDEX(PQ_Juli!$B$2:$AF$1048,MATCH($C13,PQ_Juli!$A$2:$A$1048,0),MATCH(AA$3&"",PQ_Juli!$B$1:$AF$1&"",0)),0)} -> 4 | AB13: {=IFERROR(INDEX(PQ_Juli!$B$2:$AF$1048,MATCH($C13,PQ_Juli!$A$2:$A$1048,0),MATCH(AB$3&"",PQ_Juli!$B$1:$AF$1&"",0)),0)} -> 1 | AC13: {=IFERROR(INDEX(PQ_Juli!$B$2:$AF$1048,MATCH($C13,PQ_Juli!$A$2:$A$1048,0),MATCH(AC$3&"",PQ_Juli!$B$1:$AF$1&"",0)),0)} -> 2 | AD13: {=IFERROR(INDEX(PQ_Juli!$B$2:$AF$1048,MATCH($C13,PQ_Juli!$A$2:$A$1048,0),MATCH(AD$3&"",PQ_Juli!$B$1:$AF$1&"",0)),0)} -> 2 | AE13: {=IFERROR(INDEX(PQ_Juli!$B$2:$AF$1048,MATCH($C13,PQ_Juli!$A$2:$A$1048,0),MATCH(AE$3&"",PQ_Juli!$B$1:$AF$1&"",0)),0)} -> 1 | AF13: {=IFERROR(INDEX(PQ_Juli!$B$2:$AF$1048,MATCH($C13,PQ_Juli!$A$2:$A$1048,0),MATCH(AF$3&"",PQ_Juli!$B$1:$AF$1&"",0)),0)} -> 4 | AH13: {=IFERROR(INDEX(PQ_Juli!$B$2:$AF$1048,MATCH($C13,PQ_Juli!$A$2:$A$1048,0),MATCH(AH$3&"",PQ_Juli!$B$1:$AF$1&"",0)),0)} -> 2 | AI13: {=IFERROR(INDEX(PQ_Juli!$B$2:$AF$1048,MATCH($C13,PQ_Juli!$A$2:$A$1048,0),MATCH(AI$3&"",PQ_Juli!$B$1:$AF$1&"",0)),0)} -> 1 | AJ13: {=IFERROR(INDEX(PQ_Juli!$B$2:$AF$1048,MATCH($C13,PQ_Juli!$A$2:$A$1048,0),MATCH(AJ$3&"",PQ_Juli!$B$1:$AF$1&"",0)),0)} -> 3 | AK13: {=IFERROR(INDEX(PQ_Juli!$B$2:$AF$1048,MATCH($C13,PQ_Juli!$A$2:$A$1048,0),MATCH(AK$3&"",PQ_Juli!$B$1:$AF$1&"",0)),0)} -> 0 | AL13: {=IFERROR(INDEX(PQ_Juli!$B$2:$AF$1048,MATCH($C13,PQ_Juli!$A$2:$A$1048,0),MATCH(AL$3&"",PQ_Juli!$B$1:$AF$1&"",0)),0)} -> 0 | AM13: 3 | AN13: =SUM(H13:AL13)+AM13 -> 74 | AO13: =(G13-AN13)+AZ13 -> 90 | AP13: 40 | AQ13: Pcs | AR13: 46210 | AS13: 1 | AT13: 46219 | AU13: 1 | AV13: 46213 | AW13: 46231 | AX13: =IFERROR(IF(AV13="",0,$D13*AS13),0) -> 60 | AY13: =IFERROR(IF(AW13="",0,$D13*AU13),0) -> 60 | AZ13: =AX13+AY13 -> 120 | BA13: =(G13-AN13)+AZ13 -> 90 | BN13: 42
A14: =AO14 -> #REF! | C14: Total PSA | D14: 60 | E14: 23 | F14: 20 | G14: =#REF! -> #REF! | H14: {=IFERROR(INDEX(PQ_Juli!$B$2:$AF$1048,MATCH($C14,PQ_Juli!$A$2:$A$1048,0),MATCH(H$3&"",PQ_Juli!$B$1:$AF$1&"",0)),0)} -> 0 | I14: {=IFERROR(INDEX(PQ_Juli!$B$2:$AF$1048,MATCH($C14,PQ_Juli!$A$2:$A$1048,0),MATCH(I$3&"",PQ_Juli!$B$1:$AF$1&"",0)),0)} -> 0 | J14: {=IFERROR(INDEX(PQ_Juli!$B$2:$AF$1048,MATCH($C14,PQ_Juli!$A$2:$A$1048,0),MATCH(J$3&"",PQ_Juli!$B$1:$AF$1&"",0)),0)} -> 1 | K14: {=IFERROR(INDEX(PQ_Juli!$B$2:$AF$1048,MATCH($C14,PQ_Juli!$A$2:$A$1048,0),MATCH(K$3&"",PQ_Juli!$B$1:$AF$1&"",0)),0)} -> 0 | M14: {=IFERROR(INDEX(PQ_Juli!$B$2:$AF$1048,MATCH($C14,PQ_Juli!$A$2:$A$1048,0),MATCH(M$3&"",PQ_Juli!$B$1:$AF$1&"",0)),0)} -> 1 | N14: {=IFERROR(INDEX(PQ_Juli!$B$2:$AF$1048,MATCH($C14,PQ_Juli!$A$2:$A$1048,0),MATCH(N$3&"",PQ_Juli!$B$1:$AF$1&"",0)),0)} -> 0 | O14: {=IFERROR(INDEX(PQ_Juli!$B$2:$AF$1048,MATCH($C14,PQ_Juli!$A$2:$A$1048,0),MATCH(O$3&"",PQ_Juli!$B$1:$AF$1&"",0)),0)} -> 1 | P14: {=IFERROR(INDEX(PQ_Juli!$B$2:$AF$1048,MATCH($C14,PQ_Juli!$A$2:$A$1048,0),MATCH(P$3&"",PQ_Juli!$B$1:$AF$1&"",0)),0)} -> 1 | Q14: {=IFERROR(INDEX(PQ_Juli!$B$2:$AF$1048,MATCH($C14,PQ_Juli!$A$2:$A$1048,0),MATCH(Q$3&"",PQ_Juli!$B$1:$AF$1&"",0)),0)} -> 1 | R14: {=IFERROR(INDEX(PQ_Juli!$B$2:$AF$1048,MATCH($C14,PQ_Juli!$A$2:$A$1048,0),MATCH(R$3&"",PQ_Juli!$B$1:$AF$1&"",0)),0)} -> 0 | T14: {=IFERROR(INDEX(PQ_Juli!$B$2:$AF$1048,MATCH($C14,PQ_Juli!$A$2:$A$1048,0),MATCH(T$3&"",PQ_Juli!$B$1:$AF$1&"",0)),0)} -> 0 | U14: {=IFERROR(INDEX(PQ_Juli!$B$2:$AF$1048,MATCH($C14,PQ_Juli!$A$2:$A$1048,0),MATCH(U$3&"",PQ_Juli!$B$1:$AF$1&"",0)),0)} -> 0 | V14: {=IFERROR(INDEX(PQ_Juli!$B$2:$AF$1048,MATCH($C14,PQ_Juli!$A$2:$A$1048,0),MATCH(V$3&"",PQ_Juli!$B$1:$AF$1&"",0)),0)} -> 0 | W14: {=IFERROR(INDEX(PQ_Juli!$B$2:$AF$1048,MATCH($C14,PQ_Juli!$A$2:$A$1048,0),MATCH(W$3&"",PQ_Juli!$B$1:$AF$1&"",0)),0)} -> 2 | X14: {=IFERROR(INDEX(PQ_Juli!$B$2:$AF$1048,MATCH($C14,PQ_Juli!$A$2:$A$1048,0),MATCH(X$3&"",PQ_Juli!$B$1:$AF$1&"",0)),0)} -> 1 | Y14: {=IFERROR(INDEX(PQ_Juli!$B$2:$AF$1048,MATCH($C14,PQ_Juli!$A$2:$A$1048,0),MATCH(Y$3&"",PQ_Juli!$B$1:$AF$1&"",0)),0)} -> 0 | AA14: {=IFERROR(INDEX(PQ_Juli!$B$2:$AF$1048,MATCH($C14,PQ_Juli!$A$2:$A$1048,0),MATCH(AA$3&"",PQ_Juli!$B$1:$AF$1&"",0)),0)} -> 0 | AB14: {=IFERROR(INDEX(PQ_Juli!$B$2:$AF$1048,MATCH($C14,PQ_Juli!$A$2:$A$1048,0),MATCH(AB$3&"",PQ_Juli!$B$1:$AF$1&"",0)),0)} -> 0 | AC14: {=IFERROR(INDEX(PQ_Juli!$B$2:$AF$1048,MATCH($C14,PQ_Juli!$A$2:$A$1048,0),MATCH(AC$3&"",PQ_Juli!$B$1:$AF$1&"",0)),0)} -> 0 | AD14: {=IFERROR(INDEX(PQ_Juli!$B$2:$AF$1048,MATCH($C14,PQ_Juli!$A$2:$A$1048,0),MATCH(AD$3&"",PQ_Juli!$B$1:$AF$1&"",0)),0)} -> 0 | AE14: {=IFERROR(INDEX(PQ_Juli!$B$2:$AF$1048,MATCH($C14,PQ_Juli!$A$2:$A$1048,0),MATCH(AE$3&"",PQ_Juli!$B$1:$AF$1&"",0)),0)} -> 1 | AF14: {=IFERROR(INDEX(PQ_Juli!$B$2:$AF$1048,MATCH($C14,PQ_Juli!$A$2:$A$1048,0),MATCH(AF$3&"",PQ_Juli!$B$1:$AF$1&"",0)),0)} -> 0 | AH14: {=IFERROR(INDEX(PQ_Juli!$B$2:$AF$1048,MATCH($C14,PQ_Juli!$A$2:$A$1048,0),MATCH(AH$3&"",PQ_Juli!$B$1:$AF$1&"",0)),0)} -> 0 | AI14: {=IFERROR(INDEX(PQ_Juli!$B$2:$AF$1048,MATCH($C14,PQ_Juli!$A$2:$A$1048,0),MATCH(AI$3&"",PQ_Juli!$B$1:$AF$1&"",0)),0)} -> 0 | AJ14: {=IFERROR(INDEX(PQ_Juli!$B$2:$AF$1048,MATCH($C14,PQ_Juli!$A$2:$A$1048,0),MATCH(AJ$3&"",PQ_Juli!$B$1:$AF$1&"",0)),0)} -> 0 | AK14: {=IFERROR(INDEX(PQ_Juli!$B$2:$AF$1048,MATCH($C14,PQ_Juli!$A$2:$A$1048,0),MATCH(AK$3&"",PQ_Juli!$B$1:$AF$1&"",0)),0)} -> 0 | AL14: {=IFERROR(INDEX(PQ_Juli!$B$2:$AF$1048,MATCH($C14,PQ_Juli!$A$2:$A$1048,0),MATCH(AL$3&"",PQ_Juli!$B$1:$AF$1&"",0)),0)} -> 0 | AN14: =SUM(H14:AL14)+AM14 -> 9 | AO14: =(G14-AN14)+AZ14 -> #REF! | AP14: 20 | AQ14: Pcs | AX14: =IFERROR(IF(AV14="",0,$D14*AS14),0) -> 0 | AY14: =IFERROR(IF(AW14="",0,$D14*AU14),0) -> 0 | AZ14: =AX14+AY14 -> 0 | BA14: =(G14-AN14)+AZ14 -> #REF! | BN14: 21
A15: =AO15 -> #REF! | C15: Elecsys CEA | D15: 100 | E15: 73 | F15: 29 | G15: =#REF! -> #REF! | H15: {=IFERROR(INDEX(PQ_Juli!$B$2:$AF$1048,MATCH($C15,PQ_Juli!$A$2:$A$1048,0),MATCH(H$3&"",PQ_Juli!$B$1:$AF$1&"",0)),0)} -> 1 | I15: {=IFERROR(INDEX(PQ_Juli!$B$2:$AF$1048,MATCH($C15,PQ_Juli!$A$2:$A$1048,0),MATCH(I$3&"",PQ_Juli!$B$1:$AF$1&"",0)),0)} -> 2 | J15: {=IFERROR(INDEX(PQ_Juli!$B$2:$AF$1048,MATCH($C15,PQ_Juli!$A$2:$A$1048,0),MATCH(J$3&"",PQ_Juli!$B$1:$AF$1&"",0)),0)} -> 2 | K15: {=IFERROR(INDEX(PQ_Juli!$B$2:$AF$1048,MATCH($C15,PQ_Juli!$A$2:$A$1048,0),MATCH(K$3&"",PQ_Juli!$B$1:$AF$1&"",0)),0)} -> 1 | M15: {=IFERROR(INDEX(PQ_Juli!$B$2:$AF$1048,MATCH($C15,PQ_Juli!$A$2:$A$1048,0),MATCH(M$3&"",PQ_Juli!$B$1:$AF$1&"",0)),0)} -> 0 | N15: {=IFERROR(INDEX(PQ_Juli!$B$2:$AF$1048,MATCH($C15,PQ_Juli!$A$2:$A$1048,0),MATCH(N$3&"",PQ_Juli!$B$1:$AF$1&"",0)),0)} -> 0 | O15: {=IFERROR(INDEX(PQ_Juli!$B$2:$AF$1048,MATCH($C15,PQ_Juli!$A$2:$A$1048,0),MATCH(O$3&"",PQ_Juli!$B$1:$AF$1&"",0)),0)} -> 0 | P15: {=IFERROR(INDEX(PQ_Juli!$B$2:$AF$1048,MATCH($C15,PQ_Juli!$A$2:$A$1048,0),MATCH(P$3&"",PQ_Juli!$B$1:$AF$1&"",0)),0)} -> 0 | Q15: {=IFERROR(INDEX(PQ_Juli!$B$2:$AF$1048,MATCH($C15,PQ_Juli!$A$2:$A$1048,0),MATCH(Q$3&"",PQ_Juli!$B$1:$AF$1&"",0)),0)} -> 2 | R15: {=IFERROR(INDEX(PQ_Juli!$B$2:$AF$1048,MATCH($C15,PQ_Juli!$A$2:$A$1048,0),MATCH(R$3&"",PQ_Juli!$B$1:$AF$1&"",0)),0)} -> 0 | T15: {=IFERROR(INDEX(PQ_Juli!$B$2:$AF$1048,MATCH($C15,PQ_Juli!$A$2:$A$1048,0),MATCH(T$3&"",PQ_Juli!$B$1:$AF$1&"",0)),0)} -> 0 | U15: {=IFERROR(INDEX(PQ_Juli!$B$2:$AF$1048,MATCH($C15,PQ_Juli!$A$2:$A$1048,0),MATCH(U$3&"",PQ_Juli!$B$1:$AF$1&"",0)),0)} -> 0 | V15: {=IFERROR(INDEX(PQ_Juli!$B$2:$AF$1048,MATCH($C15,PQ_Juli!$A$2:$A$1048,0),MATCH(V$3&"",PQ_Juli!$B$1:$AF$1&"",0)),0)} -> 0 | W15: {=IFERROR(INDEX(PQ_Juli!$B$2:$AF$1048,MATCH($C15,PQ_Juli!$A$2:$A$1048,0),MATCH(W$3&"",PQ_Juli!$B$1:$AF$1&"",0)),0)} -> 3 | X15: {=IFERROR(INDEX(PQ_Juli!$B$2:$AF$1048,MATCH($C15,PQ_Juli!$A$2:$A$1048,0),MATCH(X$3&"",PQ_Juli!$B$1:$AF$1&"",0)),0)} -> 0 | Y15: {=IFERROR(INDEX(PQ_Juli!$B$2:$AF$1048,MATCH($C15,PQ_Juli!$A$2:$A$1048,0),MATCH(Y$3&"",PQ_Juli!$B$1:$AF$1&"",0)),0)} -> 1 | AA15: {=IFERROR(INDEX(PQ_Juli!$B$2:$AF$1048,MATCH($C15,PQ_Juli!$A$2:$A$1048,0),MATCH(AA$3&"",PQ_Juli!$B$1:$AF$1&"",0)),0)} -> 0 | AB15: {=IFERROR(INDEX(PQ_Juli!$B$2:$AF$1048,MATCH($C15,PQ_Juli!$A$2:$A$1048,0),MATCH(AB$3&"",PQ_Juli!$B$1:$AF$1&"",0)),0)} -> 1 | AC15: {=IFERROR(INDEX(PQ_Juli!$B$2:$AF$1048,MATCH($C15,PQ_Juli!$A$2:$A$1048,0),MATCH(AC$3&"",PQ_Juli!$B$1:$AF$1&"",0)),0)} -> 2 | AD15: {=IFERROR(INDEX(PQ_Juli!$B$2:$AF$1048,MATCH($C15,PQ_Juli!$A$2:$A$1048,0),MATCH(AD$3&"",PQ_Juli!$B$1:$AF$1&"",0)),0)} -> 0 | AE15: {=IFERROR(INDEX(PQ_Juli!$B$2:$AF$1048,MATCH($C15,PQ_Juli!$A$2:$A$1048,0),MATCH(AE$3&"",PQ_Juli!$B$1:$AF$1&"",0)),0)} -> 0 | AF15: {=IFERROR(INDEX(PQ_Juli!$B$2:$AF$1048,MATCH($C15,PQ_Juli!$A$2:$A$1048,0),MATCH(AF$3&"",PQ_Juli!$B$1:$AF$1&"",0)),0)} -> 0 | AH15: {=IFERROR(INDEX(PQ_Juli!$B$2:$AF$1048,MATCH($C15,PQ_Juli!$A$2:$A$1048,0),MATCH(AH$3&"",PQ_Juli!$B$1:$AF$1&"",0)),0)} -> 0 | AI15: {=IFERROR(INDEX(PQ_Juli!$B$2:$AF$1048,MATCH($C15,PQ_Juli!$A$2:$A$1048,0),MATCH(AI$3&"",PQ_Juli!$B$1:$AF$1&"",0)),0)} -> 2 | AJ15: {=IFERROR(INDEX(PQ_Juli!$B$2:$AF$1048,MATCH($C15,PQ_Juli!$A$2:$A$1048,0),MATCH(AJ$3&"",PQ_Juli!$B$1:$AF$1&"",0)),0)} -> 0 | AK15: {=IFERROR(INDEX(PQ_Juli!$B$2:$AF$1048,MATCH($C15,PQ_Juli!$A$2:$A$1048,0),MATCH(AK$3&"",PQ_Juli!$B$1:$AF$1&"",0)),0)} -> 0 | AL15: {=IFERROR(INDEX(PQ_Juli!$B$2:$AF$1048,MATCH($C15,PQ_Juli!$A$2:$A$1048,0),MATCH(AL$3&"",PQ_Juli!$B$1:$AF$1&"",0)),0)} -> 1 | AM15: 20 | AN15: =SUM(H15:AL15)+AM15 -> 38 | AO15: =(G15-AN15)+AZ15 -> #REF! | AP15: 30 | AQ15: Pcs | AX15: =IFERROR(IF(AV15="",0,$D15*AS15),0) -> 0 | AY15: =IFERROR(IF(AW15="",0,$D15*AU15),0) -> 0 | AZ15: =AX15+AY15 -> 0 | BA15: =(G15-AN15)+AZ15 -> #REF! | BN15: 102
A16: =AO16 -> 46 | C16: Ferritin | D16: 60 | E16: 30 | F16: 23 | G16: 28 | H16: {=IFERROR(INDEX(PQ_Juli!$B$2:$AF$1048,MATCH($C16,PQ_Juli!$A$2:$A$1048,0),MATCH(H$3&"",PQ_Juli!$B$1:$AF$1&"",0)),0)} -> 0 | I16: {=IFERROR(INDEX(PQ_Juli!$B$2:$AF$1048,MATCH($C16,PQ_Juli!$A$2:$A$1048,0),MATCH(I$3&"",PQ_Juli!$B$1:$AF$1&"",0)),0)} -> 0 | J16: {=IFERROR(INDEX(PQ_Juli!$B$2:$AF$1048,MATCH($C16,PQ_Juli!$A$2:$A$1048,0),MATCH(J$3&"",PQ_Juli!$B$1:$AF$1&"",0)),0)} -> 0 | K16: {=IFERROR(INDEX(PQ_Juli!$B$2:$AF$1048,MATCH($C16,PQ_Juli!$A$2:$A$1048,0),MATCH(K$3&"",PQ_Juli!$B$1:$AF$1&"",0)),0)} -> 0 | M16: {=IFERROR(INDEX(PQ_Juli!$B$2:$AF$1048,MATCH($C16,PQ_Juli!$A$2:$A$1048,0),MATCH(M$3&"",PQ_Juli!$B$1:$AF$1&"",0)),0)} -> 3 | N16: {=IFERROR(INDEX(PQ_Juli!$B$2:$AF$1048,MATCH($C16,PQ_Juli!$A$2:$A$1048,0),MATCH(N$3&"",PQ_Juli!$B$1:$AF$1&"",0)),0)} -> 0 | O16: {=IFERROR(INDEX(PQ_Juli!$B$2:$AF$1048,MATCH($C16,PQ_Juli!$A$2:$A$1048,0),MATCH(O$3&"",PQ_Juli!$B$1:$AF$1&"",0)),0)} -> 3 | P16: {=IFERROR(INDEX(PQ_Juli!$B$2:$AF$1048,MATCH($C16,PQ_Juli!$A$2:$A$1048,0),MATCH(P$3&"",PQ_Juli!$B$1:$AF$1&"",0)),0)} -> 0 | Q16: {=IFERROR(INDEX(PQ_Juli!$B$2:$AF$1048,MATCH($C16,PQ_Juli!$A$2:$A$1048,0),MATCH(Q$3&"",PQ_Juli!$B$1:$AF$1&"",0)),0)} -> 1 | R16: {=IFERROR(INDEX(PQ_Juli!$B$2:$AF$1048,MATCH($C16,PQ_Juli!$A$2:$A$1048,0),MATCH(R$3&"",PQ_Juli!$B$1:$AF$1&"",0)),0)} -> 2 | T16: {=IFERROR(INDEX(PQ_Juli!$B$2:$AF$1048,MATCH($C16,PQ_Juli!$A$2:$A$1048,0),MATCH(T$3&"",PQ_Juli!$B$1:$AF$1&"",0)),0)} -> 3 | U16: {=IFERROR(INDEX(PQ_Juli!$B$2:$AF$1048,MATCH($C16,PQ_Juli!$A$2:$A$1048,0),MATCH(U$3&"",PQ_Juli!$B$1:$AF$1&"",0)),0)} -> 0 | V16: {=IFERROR(INDEX(PQ_Juli!$B$2:$AF$1048,MATCH($C16,PQ_Juli!$A$2:$A$1048,0),MATCH(V$3&"",PQ_Juli!$B$1:$AF$1&"",0)),0)} -> 0 | W16: {=IFERROR(INDEX(PQ_Juli!$B$2:$AF$1048,MATCH($C16,PQ_Juli!$A$2:$A$1048,0),MATCH(W$3&"",PQ_Juli!$B$1:$AF$1&"",0)),0)} -> 2 | X16: {=IFERROR(INDEX(PQ_Juli!$B$2:$AF$1048,MATCH($C16,PQ_Juli!$A$2:$A$1048,0),MATCH(X$3&"",PQ_Juli!$B$1:$AF$1&"",0)),0)} -> 1 | Y16: {=IFERROR(INDEX(PQ_Juli!$B$2:$AF$1048,MATCH($C16,PQ_Juli!$A$2:$A$1048,0),MATCH(Y$3&"",PQ_Juli!$B$1:$AF$1&"",0)),0)} -> 1 | AA16: {=IFERROR(INDEX(PQ_Juli!$B$2:$AF$1048,MATCH($C16,PQ_Juli!$A$2:$A$1048,0),MATCH(AA$3&"",PQ_Juli!$B$1:$AF$1&"",0)),0)} -> 6 | AB16: {=IFERROR(INDEX(PQ_Juli!$B$2:$AF$1048,MATCH($C16,PQ_Juli!$A$2:$A$1048,0),MATCH(AB$3&"",PQ_Juli!$B$1:$AF$1&"",0)),0)} -> 1 | AC16: {=IFERROR(INDEX(PQ_Juli!$B$2:$AF$1048,MATCH($C16,PQ_Juli!$A$2:$A$1048,0),MATCH(AC$3&"",PQ_Juli!$B$1:$AF$1&"",0)),0)} -> 0 | AD16: {=IFERROR(INDEX(PQ_Juli!$B$2:$AF$1048,MATCH($C16,PQ_Juli!$A$2:$A$1048,0),MATCH(AD$3&"",PQ_Juli!$B$1:$AF$1&"",0)),0)} -> 0 | AE16: {=IFERROR(INDEX(PQ_Juli!$B$2:$AF$1048,MATCH($C16,PQ_Juli!$A$2:$A$1048,0),MATCH(AE$3&"",PQ_Juli!$B$1:$AF$1&"",0)),0)} -> 0 | AF16: {=IFERROR(INDEX(PQ_Juli!$B$2:$AF$1048,MATCH($C16,PQ_Juli!$A$2:$A$1048,0),MATCH(AF$3&"",PQ_Juli!$B$1:$AF$1&"",0)),0)} -> 6 | AH16: {=IFERROR(INDEX(PQ_Juli!$B$2:$AF$1048,MATCH($C16,PQ_Juli!$A$2:$A$1048,0),MATCH(AH$3&"",PQ_Juli!$B$1:$AF$1&"",0)),0)} -> 2 | AI16: {=IFERROR(INDEX(PQ_Juli!$B$2:$AF$1048,MATCH($C16,PQ_Juli!$A$2:$A$1048,0),MATCH(AI$3&"",PQ_Juli!$B$1:$AF$1&"",0)),0)} -> 1 | AJ16: {=IFERROR(INDEX(PQ_Juli!$B$2:$AF$1048,MATCH($C16,PQ_Juli!$A$2:$A$1048,0),MATCH(AJ$3&"",PQ_Juli!$B$1:$AF$1&"",0)),0)} -> 2 | AK16: {=IFERROR(INDEX(PQ_Juli!$B$2:$AF$1048,MATCH($C16,PQ_Juli!$A$2:$A$1048,0),MATCH(AK$3&"",PQ_Juli!$B$1:$AF$1&"",0)),0)} -> 1 | AL16: {=IFERROR(INDEX(PQ_Juli!$B$2:$AF$1048,MATCH($C16,PQ_Juli!$A$2:$A$1048,0),MATCH(AL$3&"",PQ_Juli!$B$1:$AF$1&"",0)),0)} -> 1 | AM16: 6 | AN16: =SUM(H16:AL16)+AM16 -> 42 | AO16: =(G16-AN16)+AZ16 -> 46 | AP16: 20 | AQ16: Pcs | AR16: 46210 | AS16: 1 | AV16: 46213 | AX16: =IFERROR(IF(AV16="",0,$D16*AS16),0) -> 60 | AY16: =IFERROR(IF(AW16="",0,$D16*AU16),0) -> 0 | AZ16: =AX16+AY16 -> 60 | BA16: =(G16-AN16)+AZ16 -> 46 | BN16: 40
A17: =AO17 -> 31 | C17: IgE Total | D17: 60 | E17: 30 | F17: 40 | G17: 68 | H17: {=IFERROR(INDEX(PQ_Juli!$B$2:$AF$1048,MATCH($C17,PQ_Juli!$A$2:$A$1048,0),MATCH(H$3&"",PQ_Juli!$B$1:$AF$1&"",0)),0)} -> 1 | I17: {=IFERROR(INDEX(PQ_Juli!$B$2:$AF$1048,MATCH($C17,PQ_Juli!$A$2:$A$1048,0),MATCH(I$3&"",PQ_Juli!$B$1:$AF$1&"",0)),0)} -> 3 | J17: {=IFERROR(INDEX(PQ_Juli!$B$2:$AF$1048,MATCH($C17,PQ_Juli!$A$2:$A$1048,0),MATCH(J$3&"",PQ_Juli!$B$1:$AF$1&"",0)),0)} -> 3 | K17: {=IFERROR(INDEX(PQ_Juli!$B$2:$AF$1048,MATCH($C17,PQ_Juli!$A$2:$A$1048,0),MATCH(K$3&"",PQ_Juli!$B$1:$AF$1&"",0)),0)} -> 3 | M17: {=IFERROR(INDEX(PQ_Juli!$B$2:$AF$1048,MATCH($C17,PQ_Juli!$A$2:$A$1048,0),MATCH(M$3&"",PQ_Juli!$B$1:$AF$1&"",0)),0)} -> 1 | N17: {=IFERROR(INDEX(PQ_Juli!$B$2:$AF$1048,MATCH($C17,PQ_Juli!$A$2:$A$1048,0),MATCH(N$3&"",PQ_Juli!$B$1:$AF$1&"",0)),0)} -> 0 | O17: {=IFERROR(INDEX(PQ_Juli!$B$2:$AF$1048,MATCH($C17,PQ_Juli!$A$2:$A$1048,0),MATCH(O$3&"",PQ_Juli!$B$1:$AF$1&"",0)),0)} -> 1 | P17: {=IFERROR(INDEX(PQ_Juli!$B$2:$AF$1048,MATCH($C17,PQ_Juli!$A$2:$A$1048,0),MATCH(P$3&"",PQ_Juli!$B$1:$AF$1&"",0)),0)} -> 0 | Q17: {=IFERROR(INDEX(PQ_Juli!$B$2:$AF$1048,MATCH($C17,PQ_Juli!$A$2:$A$1048,0),MATCH(Q$3&"",PQ_Juli!$B$1:$AF$1&"",0)),0)} -> 0 | R17: {=IFERROR(INDEX(PQ_Juli!$B$2:$AF$1048,MATCH($C17,PQ_Juli!$A$2:$A$1048,0),MATCH(R$3&"",PQ_Juli!$B$1:$AF$1&"",0)),0)} -> 0 | T17: {=IFERROR(INDEX(PQ_Juli!$B$2:$AF$1048,MATCH($C17,PQ_Juli!$A$2:$A$1048,0),MATCH(T$3&"",PQ_Juli!$B$1:$AF$1&"",0)),0)} -> 2 | U17: {=IFERROR(INDEX(PQ_Juli!$B$2:$AF$1048,MATCH($C17,PQ_Juli!$A$2:$A$1048,0),MATCH(U$3&"",PQ_Juli!$B$1:$AF$1&"",0)),0)} -> 1 | V17: {=IFERROR(INDEX(PQ_Juli!$B$2:$AF$1048,MATCH($C17,PQ_Juli!$A$2:$A$1048,0),MATCH(V$3&"",PQ_Juli!$B$1:$AF$1&"",0)),0)} -> 1 | W17: {=IFERROR(INDEX(PQ_Juli!$B$2:$AF$1048,MATCH($C17,PQ_Juli!$A$2:$A$1048,0),MATCH(W$3&"",PQ_Juli!$B$1:$AF$1&"",0)),0)} -> 5 | X17: {=IFERROR(INDEX(PQ_Juli!$B$2:$AF$1048,MATCH($C17,PQ_Juli!$A$2:$A$1048,0),MATCH(X$3&"",PQ_Juli!$B$1:$AF$1&"",0)),0)} -> 0 | Y17: {=IFERROR(INDEX(PQ_Juli!$B$2:$AF$1048,MATCH($C17,PQ_Juli!$A$2:$A$1048,0),MATCH(Y$3&"",PQ_Juli!$B$1:$AF$1&"",0)),0)} -> 1 | AA17: {=IFERROR(INDEX(PQ_Juli!$B$2:$AF$1048,MATCH($C17,PQ_Juli!$A$2:$A$1048,0),MATCH(AA$3&"",PQ_Juli!$B$1:$AF$1&"",0)),0)} -> 1 | AB17: {=IFERROR(INDEX(PQ_Juli!$B$2:$AF$1048,MATCH($C17,PQ_Juli!$A$2:$A$1048,0),MATCH(AB$3&"",PQ_Juli!$B$1:$AF$1&"",0)),0)} -> 3 | AC17: {=IFERROR(INDEX(PQ_Juli!$B$2:$AF$1048,MATCH($C17,PQ_Juli!$A$2:$A$1048,0),MATCH(AC$3&"",PQ_Juli!$B$1:$AF$1&"",0)),0)} -> 2 | AD17: {=IFERROR(INDEX(PQ_Juli!$B$2:$AF$1048,MATCH($C17,PQ_Juli!$A$2:$A$1048,0),MATCH(AD$3&"",PQ_Juli!$B$1:$AF$1&"",0)),0)} -> 2 | AE17: {=IFERROR(INDEX(PQ_Juli!$B$2:$AF$1048,MATCH($C17,PQ_Juli!$A$2:$A$1048,0),MATCH(AE$3&"",PQ_Juli!$B$1:$AF$1&"",0)),0)} -> 0 | AF17: {=IFERROR(INDEX(PQ_Juli!$B$2:$AF$1048,MATCH($C17,PQ_Juli!$A$2:$A$1048,0),MATCH(AF$3&"",PQ_Juli!$B$1:$AF$1&"",0)),0)} -> 1 | AH17: {=IFERROR(INDEX(PQ_Juli!$B$2:$AF$1048,MATCH($C17,PQ_Juli!$A$2:$A$1048,0),MATCH(AH$3&"",PQ_Juli!$B$1:$AF$1&"",0)),0)} -> 1 | AI17: {=IFERROR(INDEX(PQ_Juli!$B$2:$AF$1048,MATCH($C17,PQ_Juli!$A$2:$A$1048,0),MATCH(AI$3&"",PQ_Juli!$B$1:$AF$1&"",0)),0)} -> 1 | AJ17: {=IFERROR(INDEX(PQ_Juli!$B$2:$AF$1048,MATCH($C17,PQ_Juli!$A$2:$A$1048,0),MATCH(AJ$3&"",PQ_Juli!$B$1:$AF$1&"",0)),0)} -> 1 | AK17: {=IFERROR(INDEX(PQ_Juli!$B$2:$AF$1048,MATCH($C17,PQ_Juli!$A$2:$A$1048,0),MATCH(AK$3&"",PQ_Juli!$B$1:$AF$1&"",0)),0)} -> 0 | AL17: {=IFERROR(INDEX(PQ_Juli!$B$2:$AF$1048,MATCH($C17,PQ_Juli!$A$2:$A$1048,0),MATCH(AL$3&"",PQ_Juli!$B$1:$AF$1&"",0)),0)} -> 0 | AM17: 3 | AN17: =SUM(H17:AL17)+AM17 -> 37 | AO17: =(G17-AN17)+AZ17 -> 31 | AP17: 20 | AQ17: Pcs | AX17: =IFERROR(IF(AV17="",0,$D17*AS17),0) -> 0 | AY17: =IFERROR(IF(AW17="",0,$D17*AU17),0) -> 0 | AZ17: =AX17+AY17 -> 0 | BA17: =(G17-AN17)+AZ17 -> 31 | BN17: 72
